Workbook

Sheet Teams
A2: Team Name | B2: Total | C2: Score Running | D2: Score Relays | E2: Score Field Events | F2: Athlete Name
A3: Orange Team | F3: Thea | G3: Evelyn | H3: Cosette | I3: Addis | J3: Ben | K3: Saoirse | L3: Ava M. | M3: Duyen | N3: Nick* | O3: Julia* | P3: Abby | Q3: Alex
A4: Green Team | F4: Keva | G4: Harry | H4: Cora E. | I4: Sage | J4: Grant | K4: Cora C. | L4: Greyson | M4: Sylvia | N4: Michael | O4: Ayvalyn* | P4: Eva O.* | Q4: Naomi (not competing)
A5: Yellow Team | F5: Vienna | G5: Ari | H5: Mattais | I5: Cailee | J5: Salahdin | K5: Arthur | L5: Andrew | M5: Anika | N5: Christoper | O5: Xavier* | P5: Salome*
A6: Blue Team | F6: Freyja | G6: Silas | H6: Leo | I6: Avery | J6: Isabel | K6: Ada | L6: Santiago | M6: Sawyer | N6: Albin | O6: Mitch* | P6: Brianna
A7: *Captains

Sheet Totals
A1: Team Number | B1: Team1 | C1: Team2 | D1: Team3 | E1: Team4 | G1: Events: | I1: Name | J1: Team | K1: Grade
A2: Team Name | B2: Robert | C2: Imagine Pope Kiwis III | D2: Red Dead Cheetahs | E2: Jurassic Chickens | G2: Shot | I2: Saoirse | J2: =$B$2 -> Robert | K2: 8
A3: Scoring - Running Events | B3: =sumif('Scoring - Running Events'!A:A,B2,'Scoring - Running Events'!G:G) -> 134 | C3: =sumif('Scoring - Running Events'!A:A,C2,'Scoring - Running Events'!G:G) -> 204 | D3: =sumif('Scoring - Running Events'!A:A,D2,'Scoring - Running Events'!G:G) -> 88 | E3: =sumif('Scoring - Running Events'!A:A,E2,'Scoring - Running Events'!G:G) -> 134 | G3: Disc | I3: Orianna | J3: =$B$2 -> Robert | K3: 8
A4: Scoring - Relays | B4: =sumif('Scoring - Relays'!A:A,B2,'Scoring - Relays'!E:E) -> 48 | C4: =sumif('Scoring - Relays'!A:A,C2,'Scoring - Relays'!E:E) -> 52 | D4: =sumif('Scoring - Relays'!A:A,D2,'Scoring - Relays'!E:E) -> 46 | E4: =sumif('Scoring - Relays'!A:A,E2,'Scoring - Relays'!E:E) -> 54 | G4: Hurdles | I4: Isaac J | J4: =$B$2 -> Robert | K4: 8
A5: Scoring - Field Events | B5: =sumif('Scoring - Field Events'!A:A,B2,'Scoring - Field Events'!H:H) -> 58 | C5: =sumif('Scoring - Field Events'!A:A,C2,'Scoring - Field Events'!H:H) -> 34 | D5: =sumif('Scoring - Field Events'!A:A,D2,'Scoring - Field Events'!H:H) -> 32 | E5: =sumif('Scoring - Field Events'!A:A,E2,'Scoring - Field Events'!H:H) -> 74 | G5: 200m | I5: Rowan | J5: =$B$2 -> Robert | K5: 8
A6: Total | B6: =sum(B3:B5) -> 240 | C6: =sum(C3:C5) -> 290 | D6: =sum(D3:D5) -> 166 | E6: =sum(E3:E5) -> 262 | G6: 800m | I6: Grant | J6: =$B$2 -> Robert | K6: 7
G7: 4x100 relay | I7: Nathan | J7: =$B$2 -> Robert | K7: 7
G8: 400m | I8: Londyn | J8: =$B$2 -> Robert | K8: 7
A9: Scoring system: | B9: Individual events | G9: 100m | I9: Thea | J9: =$B$2 -> Robert | K9: 6
B10: Place | C10: Points | G10: 4x400 relay | I10: Jasper | J10: =$B$2 -> Robert | K10: 5
B11: 1st place | C11: 10 | I11: Kayleigh | J11: =$B$2 -> Robert | K11: 5
B12: 2nd place | C12: 8 | I12: Evelyn | J12: =$B$2 -> Robert | K12: 6
B13: 3rd place | C13: 6 | I13: Ben | J13: =$B$2 -> Robert | K13: 6
B14: 4th place | C14: 4 | I14: Ava | J14: =$B$2 -> Robert | K14: 5
B15: 5th place | C15: 2 | I15: Remi | J15: =$B$2 -> Robert | K15: 5
B17: Relay events | I17: Cora C | J17: =$C$2 -> Imagine Pope Kiwis III | K17: 8
B18: Place | C18: Points | I18: Santi | J18: =$C$2 -> Imagine Pope Kiwis III | K18: 8
B19: 1st place | C19: 20 | I19: Ada | J19: =$C$2 -> Imagine Pope Kiwis III | K19: 8
B20: 2nd place | C20: 16 | I20: Jonathan | J20: =$C$2 -> Imagine Pope Kiwis III | K20: 8
B21: 3rd place | C21: 12 | I21: Christopher | J21: =$C$2 -> Imagine Pope Kiwis III | K21: 8
B22: 4th place | C22: 8 | I22: Cooper | J22: =$C$2 -> Imagine Pope Kiwis III | K22: 7
B23: 5th place | C23: 4 | I23: Jin | J23: =$C$2 -> Imagine Pope Kiwis III | K23: 7
I24: Keva | J24: =$C$2 -> Imagine Pope Kiwis III | K24: 6
I25: Ari | J25: =$C$2 -> Imagine Pope Kiwis III | K25: 6
I26: Caleb | J26: =$C$2 -> Imagine Pope Kiwis III | K26: 6
I27: Quentin | J27: =$C$2 -> Imagine Pope Kiwis III | K27: 5
I28: Ethan | J28: =$C$2 -> Imagine Pope Kiwis III | K28: 5
I29: Duyen | J29: =$C$2 -> Imagine Pope Kiwis III | K29: 8
I30: Hazel C | J30: =$C$2 -> Imagine Pope Kiwis III | K30: 5
I31: Marcus | J31: =$C$2 -> Imagine Pope Kiwis III | K31: 5
I32: Owen | J32: =$D$2 -> Red Dead Cheetahs | K32: 8
I33: Naomi | J33: =$D$2 -> Red Dead Cheetahs | K33: 8
I34: Ian | J34: =$D$2 -> Red Dead Cheetahs | K34: 8
I35: Anika | J35: =$D$2 -> Red Dead Cheetahs | K35: 8
I36: Mattias | J36: =$D$2 -> Red Dead Cheetahs | K36: 7
I37: Hudson | J37: =$D$2 -> Red Dead Cheetahs | K37: 7
I38: Isabel | J38: =$D$2 -> Red Dead Cheetahs | K38: 7
I39: Grayson C | J39: =$D$2 -> Red Dead Cheetahs | K39: 6
I40: Silas | J40: =$D$2 -> Red Dead Cheetahs | K40: 6
I41: Issac W | J41: =$D$2 -> Red Dead Cheetahs | K41: 6
...

Sheet Scoring - Running Events
A1: Team | B1: Hurdles | C1: Grade | D1: Gender | E1: Time | F1: Place | G1: Score | P1: =Totals!B2 -> Robert
A2: =VLOOKUP(B2,Totals!I:J,2,false) -> Imagine Pope Kiwis III | B2: Ada | C2: {=INDEX(Totals!K:K,MATCH(B2,Totals!I:I,0))} -> 8 | D2: Female | E2: 18.08 | F2: 1 | G2: 10
A3: =VLOOKUP(B3,Totals!I:J,2,false) -> Imagine Pope Kiwis III | B3: Keva | C3: {=INDEX(Totals!K:K,MATCH(B3,Totals!I:I,0))} -> 6 | D3: Female | E3: 18.7 | F3: 1 | G3: 10
A4: =VLOOKUP(B4,Totals!I:J,2,false) -> Robert | B4: Evelyn | C4: {=INDEX(Totals!K:K,MATCH(B4,Totals!I:I,0))} -> 6 | D4: Female | E4: 21.82 | F4: 2 | G4: 8 | P4: =Totals!E2 -> Jurassic Chickens
A5: =VLOOKUP(B5,Totals!I:J,2,false) -> Imagine Pope Kiwis III | B5: Ari | C5: {=INDEX(Totals!K:K,MATCH(B5,Totals!I:I,0))} -> 6 | D5: Male | E5: 18.27 | F5: 1 | G5: 10
A6: =VLOOKUP(B6,Totals!I:J,2,false) -> Jurassic Chickens | B6: Albin | C6: {=INDEX(Totals!K:K,MATCH(B6,Totals!I:I,0))} -> 8 | D6: Male | E6: 16.6 | F6: 1 | G6: 10
A7: =VLOOKUP(B7,Totals!I:J,2,false) -> Red Dead Cheetahs | B7: Alex E | C7: {=INDEX(Totals!K:K,MATCH(B7,Totals!I:I,0))} -> 5 | D7: Female | E7: 21.83 | F7: 3 | G7: 6
A8: =VLOOKUP(B8,Totals!I:J,2,false) -> Red Dead Cheetahs | B8: Anika | C8: {=INDEX(Totals!K:K,MATCH(B8,Totals!I:I,0))} -> 8 | D8: Female | E8: 18.17 | F8: 2 | G8: 8
A9: =VLOOKUP(B9,Totals!I:J,2,false) -> Robert | B9: Nathan | C9: {=INDEX(Totals!K:K,MATCH(B9,Totals!I:I,0))} -> 7 | D9: Male | E9: 19.03 | F9: 2 | G9: 8
A10: =VLOOKUP(B10,Totals!I:J,2,false) -> Red Dead Cheetahs | B10: Gabriel | C10: {=INDEX(Totals!K:K,MATCH(B10,Totals!I:I,0))} -> 5 | D10: Male | E10: 22.5 | F10: 2 | G10: 8
A11: =VLOOKUP(B11,Totals!I:J,2,false) -> Red Dead Cheetahs | B11: Perrin | C11: {=INDEX(Totals!K:K,MATCH(B11,Totals!I:I,0))} -> 5 | D11: Female | E11: 21.93 | F11: 4 | G11: 4
A12: =VLOOKUP(B12,Totals!I:J,2,false) -> Robert | B12: Ava | C12: {=INDEX(Totals!K:K,MATCH(B12,Totals!I:I,0))} -> 5 | D12: Female | E12: 26.38 | F12: 5 | G12: 2 | P12: =Totals!D2 -> Red Dead Cheetahs
A13: =VLOOKUP(B13,Totals!I:J,2,false) -> Robert | B13: Orianna | C13: {=INDEX(Totals!K:K,MATCH(B13,Totals!I:I,0))} -> 8 | D13: Female | E13: 19 | F13: 3 | G13: 6 | P13: =Totals!C2 -> Imagine Pope Kiwis III
A14: =VLOOKUP(B14,Totals!I:J,2,false) -> Imagine Pope Kiwis III | B14: Cora C | C14: {=INDEX(Totals!K:K,MATCH(B14,Totals!I:I,0))} -> 8 | D14: Female | E14: 19.07 | F14: 4 | G14: 4
A15: =VLOOKUP(B15,Totals!I:J,2,false) -> Imagine Pope Kiwis III | B15: Cooper | C15: {=INDEX(Totals!K:K,MATCH(B15,Totals!I:I,0))} -> 7 | D15: Male | E15: 19.05 | F15: 3 | G15: 6
A16: =VLOOKUP(B16,Totals!I:J,2,false) -> Imagine Pope Kiwis III | B16: Santi | C16: {=INDEX(Totals!K:K,MATCH(B16,Totals!I:I,0))} -> 8 | D16: Male | E16: 19.36 | F16: 4 | G16: 4
A17: =VLOOKUP(B17,Totals!I:J,2,false) -> Imagine Pope Kiwis III | B17: Christopher | C17: {=INDEX(Totals!K:K,MATCH(B17,Totals!I:I,0))} -> 8 | D17: Male | E17: 19.54 | F17: 5 | G17: 2
A18: =VLOOKUP(B18,Totals!I:J,2,false) -> Jurassic Chickens | B18: Hazel H | C18: {=INDEX(Totals!K:K,MATCH(B18,Totals!I:I,0))} -> 8 | D18: Female | E18: 19.17 | F18: 5 | G18: 2
A19: =VLOOKUP(B19,Totals!I:J,2,false) -> Robert | B19: Rowan | C19: {=INDEX(Totals!K:K,MATCH(B19,Totals!I:I,0))} -> 8 | D19: Male | E19: 20.8
A20: =VLOOKUP(B20,Totals!I:J,2,false) -> Red Dead Cheetahs | B20: Isabel | C20: {=INDEX(Totals!K:K,MATCH(B20,Totals!I:I,0))} -> 7 | D20: Female | E20: 26.38
A21: =VLOOKUP(B21,Totals!I:J,2,false) -> Red Dead Cheetahs | B21: Mattias | C21: {=INDEX(Totals!K:K,MATCH(B21,Totals!I:I,0))} -> 7 | D21: Male | E21: 22
A23: Team | B23: 200m | C23: Grade | D23: Gender | E23: Time | F23: Place | G23: Score
A24: =VLOOKUP(B24,Totals!I:J,2,false) -> Red Dead Cheetahs | B24: Ian | C24: {=INDEX(Totals!K:K,MATCH(B24,Totals!I:I,0))} -> 8 | D24: Male | E24: 29.1 | F24: 1 | G24: 10
A25: =VLOOKUP(B25,Totals!I:J,2,false) -> Jurassic Chickens | B25: Amelia | C25: {=INDEX(Totals!K:K,MATCH(B25,Totals!I:I,0))} -> 5 | D25: Female | E25: 31.33 | F25: 1 | G25: 10
A26: =VLOOKUP(B26,Totals!I:J,2,false) -> Jurassic Chickens | B26: Albin | C26: {=INDEX(Totals!K:K,MATCH(B26,Totals!I:I,0))} -> 8 | D26: Male | E26: 31.03 | F26: 2 | G26: 8
A27: =VLOOKUP(B27,Totals!I:J,2,false) -> Robert | B27: Thea | C27: {=INDEX(Totals!K:K,MATCH(B27,Totals!I:I,0))} -> 6 | D27: Female | E27: 31.35 | F27: 2 | G27: 8
A28: =VLOOKUP(B28,Totals!I:J,2,false) -> Imagine Pope Kiwis III | B28: Keva | C28: {=INDEX(Totals!K:K,MATCH(B28,Totals!I:I,0))} -> 6 | D28: Female | E28: 34.55 | F28: 3 | G28: 6
A29: =VLOOKUP(B29,Totals!I:J,2,false) -> Jurassic Chickens | B29: Audrey | C29: {=INDEX(Totals!K:K,MATCH(B29,Totals!I:I,0))} -> 6 | D29: Female | E29: 37.01 | F29: 4 | G29: 4
A30: =VLOOKUP(B30,Totals!I:J,2,false) -> Imagine Pope Kiwis III | B30: Ada | C30: {=INDEX(Totals!K:K,MATCH(B30,Totals!I:I,0))} -> 8 | D30: Female | E30: 31.4 | F30: 1 | G30: 10
A31: =VLOOKUP(B31,Totals!I:J,2,false) -> Red Dead Cheetahs | B31: Perrin | C31: {=INDEX(Totals!K:K,MATCH(B31,Totals!I:I,0))} -> 5 | D31: Female | E31: 40 | F31: 5 | G31: 2
A32: =VLOOKUP(B32,Totals!I:J,2,false) -> Imagine Pope Kiwis III | B32: Cooper | C32: 8 | D32: Male | E32: 31.04 | F32: 3 | G32: 6
A33: =VLOOKUP(B33,Totals!I:J,2,false) -> Imagine Pope Kiwis III | B33: Ari | C33: {=INDEX(Totals!K:K,MATCH(B33,Totals!I:I,0))} -> 6 | D33: Male | E33: 33.1 | F33: 1 | G33: 10
A34: =VLOOKUP(B34,Totals!I:J,2,false) -> Red Dead Cheetahs | B34: Gabriel | C34: {=INDEX(Totals!K:K,MATCH(B34,Totals!I:I,0))} -> 5 | D34: Male | E34: 36 | F34: 2 | G34: 8
A35: =VLOOKUP(B35,Totals!I:J,2,false) -> Robert | B35: Nathan | C35: {=INDEX(Totals!K:K,MATCH(B35,Totals!I:I,0))} -> 7 | D35: Male | E35: 31.19 | F35: 4 | G35: 4
A36: =VLOOKUP(B36,Totals!I:J,2,false) -> Jurassic Chickens | B36: Devin | C36: {=INDEX(Totals!K:K,MATCH(B36,Totals!I:I,0))} -> 5 | D36: Male | E36: 36.9 | F36: 3 | G36: 6
A37: =VLOOKUP(B37,Totals!I:J,2,false) -> Red Dead Cheetahs | B37: Alex E | C37: {=INDEX(Totals!K:K,MATCH(B37,Totals!I:I,0))} -> 5 | D37: Female | E37: 40.46
A38: =VLOOKUP(B38,Totals!I:J,2,false) -> Imagine Pope Kiwis III | B38: Santi | C38: {=INDEX(Totals!K:K,MATCH(B38,Totals!I:I,0))} -> 8 | D38: Male | E38: 32.88 | F38: 5 | G38: 2
A39: =VLOOKUP(B39,Totals!I:J,2,false) -> Robert | B39: Evelyn | C39: {=INDEX(Totals!K:K,MATCH(B39,Totals!I:I,0))} -> 6 | D39: Female | E39: 41.61
A40: =VLOOKUP(B40,Totals!I:J,2,false) -> Imagine Pope Kiwis III | B40: Christopher | C40: {=INDEX(Totals!K:K,MATCH(B40,Totals!I:I,0))} -> 8 | D40: Male | E40: 33.66 | F40: 6
A41: =VLOOKUP(B41,Totals!I:J,2,false) -> Jurassic Chickens | B41: Addis | C41: {=INDEX(Totals!K:K,MATCH(B41,Totals!I:I,0))} -> 7 | D41: Male | E41: 34.09 | F41: 7
...

Sheet Scoring - Relays
A2: Team | B2: 4x100 Relay | C2: Time | D2: Place | E2: Score
A3: =Totals!D2 -> Red Dead Cheetahs | B3: Alex, Hudson, Gabe, Ian | C3: 1:06.39 | D3: 1 | E3: 20
A4: =Totals!E2 -> Jurassic Chickens | B4: Addis, Devin, Kai, Albin | C4: 1:06.46 | D4: 2 | E4: 18
A5: =Totals!D2 -> Red Dead Cheetahs | B5: Perrin, Issac, Isabel, Anika | C5: 1:06.54 | D5: 3 | E5: 16
A6: =Totals!C2 -> Imagine Pope Kiwis III | B6: Cora C, Marcus, Caleb, Jin | C6: 1:07.7 | D6: 4 | E6: 14
A7: =Totals!E2 -> Jurassic Chickens | B7: Amelia, Cailee, Hazel, Cora | C7: 1:07.73 | D7: 5 | E7: 12
A8: =Totals!C2 -> Imagine Pope Kiwis III | B8: Ada, Cooper, Ari, Hazel C | C8: 1:08.05 | D8: 6 | E8: 10
A9: =Totals!B2 -> Robert | B9: Saoirse Jasper Thea Grant | C9: 1:08.9 | D9: 7 | E9: 8
A10: =Totals!E2 -> Jurassic Chickens | B10: Sylvia, Reuben, Audrey, Greyson D | C10: 1:10.0 | D10: 8 | E10: 6
A11: =Totals!B2 -> Robert | B11: Evelyn Nathan Ava Rowan | C11: 1:10.72 | D11: 9 | E11: 4
A12: Robert | B12: Oriana, Keilei, Lyondon | C12: 1:11.62 | D12: 10 | E12: 2
A14: Team | B14: 4x400m Relay | C14: Time | D14: Place | E14: Score
A15: =Totals!E2 -> Jurassic Chickens | B15: Amelia, Audrey, Cora, Sawyer | C15: 0.23958333 | D15: 2 | E15: 18
A16: =Totals!E2 -> Jurassic Chickens
A17: =Totals!B2 -> Robert | B17: Ben Remi Saoirse Nathan | C17: 5:54.99 | D17: 4 | E17: 14
A18: =Totals!B2 -> Robert | B18: Thea Jasper Isaac Ava | C18: 0.23055556 | D18: 1 | E18: 20
A19: =Totals!C2 -> Imagine Pope Kiwis III | B19: Keva, Jin, Ethan, Chris | C19: 0.24583333 | D19: 3 | E19: 16
A20: =Totals!C2 -> Imagine Pope Kiwis III | B20: Cooper, Cora, Hazel C, Ada | C20: 0.24930556 | D20: 5 | E20: 12
A21: =Totals!D2 -> Red Dead Cheetahs | B21: Anika, Hudson, Gabe, Perrin | C21: 0.24930556 | D21: 6 | E21: 10
A22: =Totals!D2 -> Red Dead Cheetahs

Sheet Scoring - Field Events
A2: Team | B2: Shot Put | C2: Grade | D2: Gender | E2: Throw 1 | F2: Throw 2 | G2: Place | H2: Score
A3: =if(B3="","",(VLOOKUP(B3,Totals!I:J,2,false))) -> Jurassic Chickens | B3: Albin | C3: {=INDEX(Totals!K:K,MATCH(B3,Totals!I:I,0))} -> 8 | D3: Male | E3: 7.7 | G3: 4 | H3: 4
A4: =if(B4="","",(VLOOKUP(B4,Totals!I:J,2,false))) -> Jurassic Chickens | B4: Hazel H | C4: {=INDEX(Totals!K:K,MATCH(B4,Totals!I:I,0))} -> 8 | D4: Female | E4: 8.68 | G4: 1 | H4: 10
A5: =if(B5="","",(VLOOKUP(B5,Totals!I:J,2,false))) -> Robert | B5: Remi | C5: {=INDEX(Totals!K:K,MATCH(B5,Totals!I:I,0))} -> 5 | D5: Male | E5: 4.02 | G5: 1 | H5: 10 | N5: =Totals!D2 -> Red Dead Cheetahs
A6: =if(B6="","",(VLOOKUP(B6,Totals!I:J,2,false))) -> Robert | B6: Evelyn | C6: {=INDEX(Totals!K:K,MATCH(B6,Totals!I:I,0))} -> 6 | D6: Female | E6: 6.12 | G6: 1 | H6: 10
A7: =if(B7="","",(VLOOKUP(B7,Totals!I:J,2,false))) -> Jurassic Chickens | B7: Reuben | C7: {=INDEX(Totals!K:K,MATCH(B7,Totals!I:I,0))} -> 5 | D7: Male | E7: 4 | G7: 2 | H7: 8
A8: =if(B8="","",(VLOOKUP(B8,Totals!I:J,2,false))) -> Robert | B8: Orianna | C8: {=INDEX(Totals!K:K,MATCH(B8,Totals!I:I,0))} -> 8 | D8: Female | E8: 7.1 | G8: 2 | H8: 8 | N8: =Totals!C2 -> Imagine Pope Kiwis III
A9: =if(B9="","",(VLOOKUP(B9,Totals!I:J,2,false))) -> Red Dead Cheetahs | B9: Anika | C9: {=INDEX(Totals!K:K,MATCH(B9,Totals!I:I,0))} -> 8 | D9: Female | E9: 5.98 | G9: 3 | H9: 6
A10: =if(B10="","",(VLOOKUP(B10,Totals!I:J,2,false))) -> Robert | B10: Nathan | C10: {=INDEX(Totals!K:K,MATCH(B10,Totals!I:I,0))} -> 7 | D10: Male | E10: 6.35 | G10: 3 | H10: 6 | N10: =Totals!B2 -> Robert
A11: =if(B11="","",(VLOOKUP(B11,Totals!I:J,2,false))) -> Red Dead Cheetahs | B11: Alex E | C11: {=INDEX(Totals!K:K,MATCH(B11,Totals!I:I,0))} -> 5 | D11: Female | E11: 5 | G11: 2 | H11: 8
A12: =if(B12="","",(VLOOKUP(B12,Totals!I:J,2,false))) -> Imagine Pope Kiwis III | B12: Ethan | C12: {=INDEX(Totals!K:K,MATCH(B12,Totals!I:I,0))} -> 5 | D12: Male | E12: 3.82 | G12: 3 | H12: 6
A13: =if(B13="","",(VLOOKUP(B13,Totals!I:J,2,false))) -> Red Dead Cheetahs | B13: Hudson | C13: {=INDEX(Totals!K:K,MATCH(B13,Totals!I:I,0))} -> 7 | D13: Male | E13: 6.1 | G13: 2 | H13: 8
A14: =if(B14="","",(VLOOKUP(B14,Totals!I:J,2,false))) -> Robert | B14: Saoirse | C14: {=INDEX(Totals!K:K,MATCH(B14,Totals!I:I,0))} -> 8 | D14: Female | E14: 5.69 | G14: 4 | H14: 4
A15: =if(B15="","",(VLOOKUP(B15,Totals!I:J,2,false))) -> Jurassic Chickens | B15: Sylvia | C15: {=INDEX(Totals!K:K,MATCH(B15,Totals!I:I,0))} -> 8 | D15: Female | E15: 5.64 | G15: 5 | H15: 2
A16: =if(B16="","",(VLOOKUP(B16,Totals!I:J,2,false))) -> Jurassic Chickens | B16: Finley | C16: {=INDEX(Totals!K:K,MATCH(B16,Totals!I:I,0))} -> 5 | D16: Male | E16: 3.72 | G16: 4 | H16: 4
A17: =if(B17="","",(VLOOKUP(B17,Totals!I:J,2,false))) -> Red Dead Cheetahs | B17: Silas | C17: {=INDEX(Totals!K:K,MATCH(B17,Totals!I:I,0))} -> 6 | D17: Male | E17: 3.36 | G17: 5 | H17: 2
A18: =if(B18="","",(VLOOKUP(B18,Totals!I:J,2,false))) -> Jurassic Chickens | B18: Greyson D | C18: {=INDEX(Totals!K:K,MATCH(B18,Totals!I:I,0))} -> 8 | D18: Male | E18: 5.61 | G18: 1 | H18: 10
A19: =if(B19="","",(VLOOKUP(B19,Totals!I:J,2,false))) -> Imagine Pope Kiwis III | B19: Cora C | C19: {=INDEX(Totals!K:K,MATCH(B19,Totals!I:I,0))} -> 8 | D19: Female | E19: 4.86
A20: =if(B20="","",(VLOOKUP(B20,Totals!I:J,2,false))) -> Imagine Pope Kiwis III | B20: Christopher | C20: {=INDEX(Totals!K:K,MATCH(B20,Totals!I:I,0))} -> 8 | D20: Male
A21: =if(B21="","",(VLOOKUP(B21,Totals!I:J,2,false))) -> Imagine Pope Kiwis III | B21: Duyen | C21: {=INDEX(Totals!K:K,MATCH(B21,Totals!I:I,0))} -> 8 | D21: Female
A22: =if(B22="","",(VLOOKUP(B22,Totals!I:J,2,false)))
A23: =if(B23="","",(VLOOKUP(B23,Totals!I:J,2,false)))
A24: =if(B24="","",(VLOOKUP(B24,Totals!I:J,2,false)))
A25: =if(B25="","",(VLOOKUP(B25,Totals!I:J,2,false)))
A26: Team | B26: Discus | C26: Grade | D26: Gender | E26: Throw 1 | F26: Throw 2 | G26: Place | H26: Score
A27: =if(B27="","",(VLOOKUP(B27,Totals!I:J,2,false))) -> Jurassic Chickens | B27: Albin | C27: {=INDEX(Totals!K:K,MATCH(B27,Totals!I:I,0))} -> 8 | D27: Male | E27: 17.18 | G27: 1 | H27: 10
A28: =if(B28="","",(VLOOKUP(B28,Totals!I:J,2,false))) -> Jurassic Chickens | B28: Hazel H | C28: {=INDEX(Totals!K:K,MATCH(B28,Totals!I:I,0))} -> 8 | D28: Female | E28: 19.43 | G28: 1 | H28: 10
A29: =if(B29="","",(VLOOKUP(B29,Totals!I:J,2,false))) -> Imagine Pope Kiwis III | B29: Ari | C29: {=INDEX(Totals!K:K,MATCH(B29,Totals!I:I,0))} -> 6 | D29: Male | E29: 10.43 | G29: 1 | H29: 10
A30: =if(B30="","",(VLOOKUP(B30,Totals!I:J,2,false))) -> Jurassic Chickens | B30: Devin | C30: {=INDEX(Totals!K:K,MATCH(B30,Totals!I:I,0))} -> 5 | D30: Male | E30: 10.31 | G30: 2 | H30: 8
A31: =if(B31="","",(VLOOKUP(B31,Totals!I:J,2,false))) -> Robert | B31: Remi | C31: {=INDEX(Totals!K:K,MATCH(B31,Totals!I:I,0))} -> 5 | D31: Male | E31: 6.93 | G31: 3 | H31: 6
A32: =if(B32="","",(VLOOKUP(B32,Totals!I:J,2,false))) -> Robert | B32: Orianna | C32: {=INDEX(Totals!K:K,MATCH(B32,Totals!I:I,0))} -> 8 | D32: Female | E32: 14.38 | G32: 2 | H32: 8
A33: =if(B33="","",(VLOOKUP(B33,Totals!I:J,2,false))) -> Imagine Pope Kiwis III | B33: Keva | C33: {=INDEX(Totals!K:K,MATCH(B33,Totals!I:I,0))} -> 6 | D33: Female | E33: 11.11 | G33: 1 | H33: 10
A34: =if(B34="","",(VLOOKUP(B34,Totals!I:J,2,false))) -> Red Dead Cheetahs | B34: Gabriel | C34: {=INDEX(Totals!K:K,MATCH(B34,Totals!I:I,0))} -> 5 | D34: Male | E34: 6.69 | G34: 4 | H34: 4
A35: =if(B35="","",(VLOOKUP(B35,Totals!I:J,2,false))) -> Imagine Pope Kiwis III | B35: Marcus | C35: {=INDEX(Totals!K:K,MATCH(B35,Totals!I:I,0))} -> 5 | D35: Male | E35: 6.1 | G35: 5 | H35: 2
A36: =if(B36="","",(VLOOKUP(B36,Totals!I:J,2,false))) -> Imagine Pope Kiwis III | B36: Cora c | C36: {=INDEX(Totals!K:K,MATCH(B36,Totals!I:I,0))} -> 8 | D36: Female | E36: 9.8 | G36: 3 | H36: 6
A37: =if(B37="","",(VLOOKUP(B37,Totals!I:J,2,false))) -> Red Dead Cheetahs | B37: Anika | C37: {=INDEX(Totals!K:K,MATCH(B37,Totals!I:I,0))} -> 8 | D37: Female | E37: 9.51 | G37: 4 | H37: 4
A38: =if(B38="","",(VLOOKUP(B38,Totals!I:J,2,false))) -> Jurassic Chickens | B38: Amelia | C38: {=INDEX(Totals!K:K,MATCH(B38,Totals!I:I,0))} -> 5 | D38: Female
A39: =if(B39="","",(VLOOKUP(B39,Totals!I:J,2,false))) -> Red Dead Cheetahs | B39: Grayson C | C39: {=INDEX(Totals!K:K,MATCH(B39,Totals!I:I,0))} -> 6 | D39: Male | E39: 5.32
A40: =if(B40="","",(VLOOKUP(B40,Totals!I:J,2,false))) -> Jurassic Chickens | B40: Sawyer | C40: {=INDEX(Totals!K:K,MATCH(B40,Totals!I:I,0))} -> 8 | D40: Male | E40: 16.82 | G40: 2 | H40: 8
A41: =if(B41="","",(VLOOKUP(B41,Totals!I:J,2,false))) -> Robert | B41: Grant | C41: {=INDEX(Totals!K:K,MATCH(B41,Totals!I:I,0))} -> 7 | D41: Male | E41: 11.14 | G41: 3 | H41: 6
...
