Workbook

Sheet Instructions
A1: Yinghua Track — Parent Meet Attendance
A3: Hi parents! Please mark whether your child will attend each upcoming meet.
A5: How to use:
A6: 1. Go to the SIGN-UP tab.
A7: 2. Find your child's row (sorted alphabetically by last name).
A8: 3. For each meet column, choose Yes or No from the dropdown.
A9: 4. Optional: leave a quick note in the Comments column (e.g. arriving late, leaving early).
A11: Notes:
A12: • Two meets are middle-school only. 5th-graders' cells for those meets are grayed out — please skip them.
A13: • Coaches use the Yes/No counts at the bottom to plan transportation, heat sheets, and parent volunteers.
A14: • If you're unsure, mark Yes — it's easier for us to remove an athlete than to add one last-minute.
A16: Meet schedule:
... A22: Questions? Email Coach Drew at drewadding@gmail.com.

Sheet Roster
A1: Roster — edit here to add/remove athletes
A2: Name | B2: Grade | C2: Gender
A3: Reuben Addington | B3: 6 | C3: M
A4: Cole Beaudry | B4: 7 | C4: M
A5: Keva Bowron | B5: 7 | C5: F
A6: Teagan Bowron | B6: 5 | C6: F
A7: Liam Bursell | B7: 7 | C7: M
A8: Mila Bursell | B8: 7 | C8: F
A9: Grayson Chon | B9: 7 | C9: M
A10: Cooper Coblentz | B10: 8 | C10: M
A11: Hudson Coblentz | B11: 8 | C11: M
A12: Nathan Coblentz | B12: 8 | C12: M
A13: Addis Demere | B13: 8 | C13: M
A14: Amen Demere | B14: 5 | C14: F
... A58: Tianming Yang | B58: 5 | C58: M

Sheet Sign-Up
A1: Yinghua Track — Meet Attendance Sign-Up
A2: Athlete | C2: Pick Yes / No for each meet | G2: Summary
A3: Name | B3: Grade | C3: Wed 5/6 4:15 PM Olson MS — Bloomington (Jefferson HS) Grades 6-8 | D3: Sat 5/9 9:00 AM St. Paul Central H.S. (St. Paul Central HS) Grades 5-8 | E3: Wed 5/13 4:00 PM Prior Lake (Prior Lake HS) Grades 6-8 | F3: Fri 5/15 5:00–8:00 PM TCGIS (Concordia Academy) Grades 5-8 | G3: # Meets (yes count) | H3: Comments / notes (arriving late, leaving early, etc.)
A4: =IF(Roster!A3="","",Roster!A3) -> Reuben Addington | B4: =IF(Roster!B3="","",Roster!B3) -> 6 | C4: Yes | D4: Yes | E4: Yes | F4: Yes | G4: =IF(A4="","",COUNTIF(C4:F4,"Yes")) -> 4
A5: =IF(Roster!A4="","",Roster!A4) -> Cole Beaudry | B5: =IF(Roster!B4="","",Roster!B4) -> 7 | G5: =IF(A5="","",COUNTIF(C5:F5,"Yes")) -> 0
A6: =IF(Roster!A5="","",Roster!A5) -> Keva Bowron | B6: =IF(Roster!B5="","",Roster!B5) -> 7 | C6: Yes | D6: Yes | E6: Yes | F6: No | G6: =IF(A6="","",COUNTIF(C6:F6,"Yes")) -> 3 | H6: 8th grade dance 5-15
A7: =IF(Roster!A6="","",Roster!A6) -> Teagan Bowron | B7: =IF(Roster!B6="","",Roster!B6) -> 5 | D7: Yes | F7: No | G7: =IF(A7="","",COUNTIF(C7:F7,"Yes")) -> 1 | H7: out of town commitment 5-15
A8: =IF(Roster!A7="","",Roster!A7) -> Liam Bursell | B8: =IF(Roster!B7="","",Roster!B7) -> 7 | G8: =IF(A8="","",COUNTIF(C8:F8,"Yes")) -> 0
A9: =IF(Roster!A8="","",Roster!A8) -> Mila Bursell | B9: =IF(Roster!B8="","",Roster!B8) -> 7 | G9: =IF(A9="","",COUNTIF(C9:F9,"Yes")) -> 0
A10: =IF(Roster!A9="","",Roster!A9) -> Grayson Chon | B10: =IF(Roster!B9="","",Roster!B9) -> 7 | E10: No | F10: Yes | G10: =IF(A10="","",COUNTIF(C10:F10,"Yes")) -> 1
A11: =IF(Roster!A10="","",Roster!A10) -> Cooper Coblentz | B11: =IF(Roster!B10="","",Roster!B10) -> 8 | C11: Yes | D11: Yes | E11: No | G11: =IF(A11="","",COUNTIF(C11:F11,"Yes")) -> 2
A12: =IF(Roster!A11="","",Roster!A11) -> Hudson Coblentz | B12: =IF(Roster!B11="","",Roster!B11) -> 8 | C12: Yes | D12: Yes | E12: No | G12: =IF(A12="","",COUNTIF(C12:F12,"Yes")) -> 2
A13: =IF(Roster!A12="","",Roster!A12) -> Nathan Coblentz | B13: =IF(Roster!B12="","",Roster!B12) -> 8 | C13: Yes | D13: Yes | E13: No | G13: =IF(A13="","",COUNTIF(C13:F13,"Yes")) -> 2
A14: =IF(Roster!A13="","",Roster!A13) -> Addis Demere | B14: =IF(Roster!B13="","",Roster!B13) -> 8 | G14: =IF(A14="","",COUNTIF(C14:F14,"Yes")) -> 0
A15: =IF(Roster!A14="","",Roster!A14) -> Amen Demere | B15: =IF(Roster!B14="","",Roster!B14) -> 5 | G15: =IF(A15="","",COUNTIF(C15:F15,"Yes")) -> 0
A16: =IF(Roster!A15="","",Roster!A15) -> Kai Dinger | B16: =IF(Roster!B15="","",Roster!B15) -> 7 | C16: Yes | D16: Yes | E16: Yes | F16: No | G16: =IF(A16="","",COUNTIF(C16:F16,"Yes")) -> 3
A17: =IF(Roster!A16="","",Roster!A16) -> Alexandra Ebinger | B17: =IF(Roster!B16="","",Roster!B16) -> 6 | C17: Yes | D17: No | E17: Yes | F17: No | G17: =IF(A17="","",COUNTIF(C17:F17,"Yes")) -> 2
A18: =IF(Roster!A17="","",Roster!A17) -> Cora Ebinger | B18: =IF(Roster!B17="","",Roster!B17) -> 8 | C18: No | D18: No | E18: No | F18: No | G18: =IF(A18="","",COUNTIF(C18:F18,"Yes")) -> 0
A19: =IF(Roster!A18="","",Roster!A18) -> Jace Euphosin | B19: =IF(Roster!B18="","",Roster!B18) -> 5 | C19: No | D19: Yes | F19: Yes | G19: =IF(A19="","",COUNTIF(C19:F19,"Yes")) -> 2
A20: =IF(Roster!A19="","",Roster!A19) -> Althea Bortel Fielder | B20: =IF(Roster!B19="","",Roster!B19) -> 7 | C20: Yes | D20: Yes | G20: =IF(A20="","",COUNTIF(C20:F20,"Yes")) -> 2
A21: =IF(Roster!A20="","",Roster!A20) -> Elyse Folbrecht | B21: =IF(Roster!B20="","",Roster!B20) -> 6 | C21: Yes | D21: Yes | E21: Yes | F21: Yes | G21: =IF(A21="","",COUNTIF(C21:F21,"Yes")) -> 4
A22: =IF(Roster!A21="","",Roster!A21) -> Walter Folbrecht | B22: =IF(Roster!B21="","",Roster!B21) -> 5 | D22: Yes | F22: Yes | G22: =IF(A22="","",COUNTIF(C22:F22,"Yes")) -> 2
A23: =IF(Roster!A22="","",Roster!A22) -> Remy Fortin | B23: =IF(Roster!B22="","",Roster!B22) -> 7 | C23: Yes | D23: Yes | E23: Yes | F23: No | G23: =IF(A23="","",COUNTIF(C23:F23,"Yes")) -> 3
A24: =IF(Roster!A23="","",Roster!A23) -> Gabriella Gruber | B24: =IF(Roster!B23="","",Roster!B23) -> 5 | C24: No | D24: Yes | E24: No | F24: Yes | G24: =IF(A24="","",COUNTIF(C24:F24,"Yes")) -> 2
A25: =IF(Roster!A24="","",Roster!A24) -> Vienna Haas | B25: =IF(Roster!B24="","",Roster!B24) -> 7 | C25: Yes | D25: Yes | E25: Yes | F25: No | G25: =IF(A25="","",COUNTIF(C25:F25,"Yes")) -> 3 | H25: 5/15 No throwing events for Coach K, 8th Grade Dance for V
A26: =IF(Roster!A25="","",Roster!A25) -> Aedan Herman | B26: =IF(Roster!B25="","",Roster!B25) -> 8 | F26: No | G26: =IF(A26="","",COUNTIF(C26:F26,"Yes")) -> 0
A27: =IF(Roster!A26="","",Roster!A26) -> Louie Herman | B27: =IF(Roster!B26="","",Roster!B26) -> 5 | D27: No | F27: Yes | G27: =IF(A27="","",COUNTIF(C27:F27,"Yes")) -> 1
A28: =IF(Roster!A27="","",Roster!A27) -> Jasper Hill | B28: =IF(Roster!B27="","",Roster!B27) -> 5 | C28: No | D28: No | E28: No | F28: No | G28: =IF(A28="","",COUNTIF(C28:F28,"Yes")) -> 0
A29: =IF(Roster!A28="","",Roster!A28) -> Ben Hinrichs | B29: =IF(Roster!B28="","",Roster!B28) -> 8 | C29: No | D29: No | E29: Yes | F29: Yes | G29: =IF(A29="","",COUNTIF(C29:F29,"Yes")) -> 2
A30: =IF(Roster!A29="","",Roster!A29) -> Sage Houdek | B30: =IF(Roster!B29="","",Roster!B29) -> 8 | C30: Yes | D30: No | E30: Yes | F30: No | G30: =IF(A30="","",COUNTIF(C30:F30,"Yes")) -> 2 | H30: Sage has an orchestra concert on 5/9; 8th grade dance on 5/15
A31: =IF(Roster!A30="","",Roster!A30) -> Ari Klapperich-Khuu | B31: =IF(Roster!B30="","",Roster!B30) -> 7 | D31: Yes | E31: Yes | F31: No | G31: =IF(A31="","",COUNTIF(C31:F31,"Yes")) -> 2
A32: =IF(Roster!A31="","",Roster!A31) -> Marcus Kunc | B32: =IF(Roster!B31="","",Roster!B31) -> 6 | C32: Yes | D32: No | E32: Yes | F32: No | G32: =IF(A32="","",COUNTIF(C32:F32,"Yes")) -> 2
A33: =IF(Roster!A32="","",Roster!A32) -> Mattias Kunc | B33: =IF(Roster!B32="","",Roster!B32) -> 8 | C33: Yes | D33: No | E33: Yes | F33: No | G33: =IF(A33="","",COUNTIF(C33:F33,"Yes")) -> 2
A34: =IF(Roster!A33="","",Roster!A33) -> Avinash Landahl | B34: =IF(Roster!B33="","",Roster!B33) -> 5 | G34: =IF(A34="","",COUNTIF(C34:F34,"Yes")) -> 0
A35: =IF(Roster!A34="","",Roster!A34) -> Perrin Light-Haberstroh | B35: =IF(Roster!B34="","",Roster!B34) -> 6 | D35: No | G35: =IF(A35="","",COUNTIF(C35:F35,"Yes")) -> 0
A36: =IF(Roster!A35="","",Roster!A35) -> Devin Lindquist | B36: =IF(Roster!B35="","",Roster!B35) -> 6 | G36: =IF(A36="","",COUNTIF(C36:F36,"Yes")) -> 0
A37: =IF(Roster!A36="","",Roster!A36) -> Brighton Balk Mmary | B37: =IF(Roster!B36="","",Roster!B36) -> 5 | D37: Yes | F37: Yes | G37: =IF(A37="","",COUNTIF(C37:F37,"Yes")) -> 2
A38: =IF(Roster!A37="","",Roster!A37) -> Gabriel Nowariak | B38: =IF(Roster!B37="","",Roster!B37) -> 6 | C38: No | D38: Yes | E38: Yes | F38: No | G38: =IF(A38="","",COUNTIF(C38:F38,"Yes")) -> 2
A39: =IF(Roster!A38="","",Roster!A38) -> Annika Peterson | B39: =IF(Roster!B38="","",Roster!B38) -> 7 | C39: Yes | D39: Yes | E39: Yes | F39: No | G39: =IF(A39="","",COUNTIF(C39:F39,"Yes")) -> 3
A40: =IF(Roster!A39="","",Roster!A39) -> Cailee Pham | B40: =IF(Roster!B39="","",Roster!B39) -> 8 | G40: =IF(A40="","",COUNTIF(C40:F40,"Yes")) -> 0
...
