Workbook

Sheet Instructions
A1: Yinghua Track — Prior Lake Meet Event Signup
A3: Wednesday, May 13, 2026 · 4:15 PM at Prior Lake HS · Grades 6–8 (6th may run 7th-grade events)
A5: How to use
A6: 1. ROSTER tab — pre-filtered to athletes who said YES on the parent attendance form.
A7: 2. SIGNUP tab — type into the event columns:
A8: • X = entered in this individual event
A9: • A or B or C or D = relay team letter
A10: Leave cells blank if the athlete isn't doing that event.
A11: 3. Right-side Summary auto-counts and flags any athlete over 4 events.
A12: 4. BY EVENT tab — auto-populated heat sheet, printable for the meet.
A14: Rules
A15: • Max 4 events per athlete (combined running + field).
... A21: • Teams attending: Lakeville North, Lakeville South, Northfield, Yinghua Academy.

Sheet Roster
A1: Roster — 22 athletes attending Prior Lake Meet
A2: Name | B2: Grade | C2: Gender
A3: Reuben Addington | B3: 6 | C3: M
A4: Keva Bowron | B4: 7 | C4: F
A5: Kai Dinger | B5: 7 | C5: M
A6: Alexandra Ebinger | B6: 6 | C6: F
A7: Elyse Folbrecht | B7: 6 | C7: F
A8: Remy Fortin | B8: 7 | C8: M
A9: Vienna Haas | B9: 7 | C9: F
A10: Ben Hinrichs | B10: 8 | C10: M
A11: Sage Houdek | B11: 8 | C11: F
A12: Ari Klapperich-Khuu | B12: 7 | C12: M
A13: Marcus Kunc | B13: 6 | C13: M
A14: Mattias Kunc | B14: 8 | C14: M
... A29: Cole Beaudry | B29: 7 | C29: M

Sheet Signup
A1: Prior Lake Meet — Athlete Event Signup
D2: RUNNING EVENTS (X, or A/B/C/D for relays) | L2: FIELD EVENTS (X, or A/B/C/D for relays) | P2: SUMMARY
A3: Name | B3: Grade | C3: Gender | D3: 100mH | E3: 100m | F3: 1600m | G3: 400m | H3: 4x100 | I3: 200m | J3: 800m | K3: SMR | L3: HJ | M3: LJ | N3: SP | O3: DISC | P3: Run # | Q3: Field # | R3: Total | S3: Valid?
A4: =IF(Roster!A3="","",Roster!A3) -> Reuben Addington | B4: =IF(Roster!B3="","",Roster!B3) -> 6 | C4: =IF(Roster!C3="","",Roster!C3) -> M | E4: X | J4: X | N4: X | O4: X | P4: =IF(A4="","",COUNTA(D4:K4)) -> 2 | Q4: =IF(A4="","",COUNTA(L4:O4)) -> 2 | R4: =IF(A4="","",P4+Q4) -> 4 | S4: =IF(A4="","",IF(R4=0,"",IF(R4>4,"❌ Over 4 events",IF(AND(R4=4,NOT(OR(AND(P4=3,Q4=1),AND(P4=1,Q4=3)))),"⚠ Must be 3+1 or 1+3","✓ OK")))) -> ⚠ Must be 3+1 or 1+3
A5: =IF(Roster!A4="","",Roster!A4) -> Keva Bowron | B5: =IF(Roster!B4="","",Roster!B4) -> 7 | C5: =IF(Roster!C4="","",Roster!C4) -> F | D5: X | H5: A | I5: X | K5: A | P5: =IF(A5="","",COUNTA(D5:K5)) -> 4 | Q5: =IF(A5="","",COUNTA(L5:O5)) -> 0 | R5: =IF(A5="","",P5+Q5) -> 4 | S5: =IF(A5="","",IF(R5=0,"",IF(R5>4,"❌ Over 4 events",IF(AND(R5=4,NOT(OR(AND(P5=3,Q5=1),AND(P5=1,Q5=3)))),"⚠ Must be 3+1 or 1+3","✓ OK")))) -> ⚠ Must be 3+1 or 1+3
A6: =IF(Roster!A5="","",Roster!A5) -> Kai Dinger | B6: =IF(Roster!B5="","",Roster!B5) -> 7 | C6: =IF(Roster!C5="","",Roster!C5) -> M | E6: X | H6: B | I6: X | K6: B | P6: =IF(A6="","",COUNTA(D6:K6)) -> 4 | Q6: =IF(A6="","",COUNTA(L6:O6)) -> 0 | R6: =IF(A6="","",P6+Q6) -> 4 | S6: =IF(A6="","",IF(R6=0,"",IF(R6>4,"❌ Over 4 events",IF(AND(R6=4,NOT(OR(AND(P6=3,Q6=1),AND(P6=1,Q6=3)))),"⚠ Must be 3+1 or 1+3","✓ OK")))) -> ⚠ Must be 3+1 or 1+3
A7: =IF(Roster!A6="","",Roster!A6) -> Alexandra Ebinger | B7: =IF(Roster!B6="","",Roster!B6) -> 6 | C7: =IF(Roster!C6="","",Roster!C6) -> F | P7: =IF(A7="","",COUNTA(D7:K7)) -> 0 | Q7: =IF(A7="","",COUNTA(L7:O7)) -> 0 | R7: =IF(A7="","",P7+Q7) -> 0 | S7: =IF(A7="","",IF(R7=0,"",IF(R7>4,"❌ Over 4 events",IF(AND(R7=4,NOT(OR(AND(P7=3,Q7=1),AND(P7=1,Q7=3)))),"⚠ Must be 3+1 or 1+3","✓ OK"))))
A8: =IF(Roster!A7="","",Roster!A7) -> Elyse Folbrecht | B8: =IF(Roster!B7="","",Roster!B7) -> 6 | C8: =IF(Roster!C7="","",Roster!C7) -> F | H8: C | N8: X | O8: X | P8: =IF(A8="","",COUNTA(D8:K8)) -> 1 | Q8: =IF(A8="","",COUNTA(L8:O8)) -> 2 | R8: =IF(A8="","",P8+Q8) -> 3 | S8: =IF(A8="","",IF(R8=0,"",IF(R8>4,"❌ Over 4 events",IF(AND(R8=4,NOT(OR(AND(P8=3,Q8=1),AND(P8=1,Q8=3)))),"⚠ Must be 3+1 or 1+3","✓ OK")))) -> ✓ OK
A9: =IF(Roster!A8="","",Roster!A8) -> Remy Fortin | B9: =IF(Roster!B8="","",Roster!B8) -> 7 | C9: =IF(Roster!C8="","",Roster!C8) -> M | E9: X | I9: X | M9: X | P9: =IF(A9="","",COUNTA(D9:K9)) -> 2 | Q9: =IF(A9="","",COUNTA(L9:O9)) -> 1 | R9: =IF(A9="","",P9+Q9) -> 3 | S9: =IF(A9="","",IF(R9=0,"",IF(R9>4,"❌ Over 4 events",IF(AND(R9=4,NOT(OR(AND(P9=3,Q9=1),AND(P9=1,Q9=3)))),"⚠ Must be 3+1 or 1+3","✓ OK")))) -> ✓ OK
A10: =IF(Roster!A9="","",Roster!A9) -> Vienna Haas | B10: =IF(Roster!B9="","",Roster!B9) -> 7 | C10: =IF(Roster!C9="","",Roster!C9) -> F | D10: X | H10: A | K10: A | O10: X | P10: =IF(A10="","",COUNTA(D10:K10)) -> 3 | Q10: =IF(A10="","",COUNTA(L10:O10)) -> 1 | R10: =IF(A10="","",P10+Q10) -> 4 | S10: =IF(A10="","",IF(R10=0,"",IF(R10>4,"❌ Over 4 events",IF(AND(R10=4,NOT(OR(AND(P10=3,Q10=1),AND(P10=1,Q10=3)))),"⚠ Must be 3+1 or 1+3","✓ OK")))) -> ✓ OK
A11: =IF(Roster!A10="","",Roster!A10) -> Ben Hinrichs | B11: =IF(Roster!B10="","",Roster!B10) -> 8 | C11: =IF(Roster!C10="","",Roster!C10) -> M | P11: =IF(A11="","",COUNTA(D11:K11)) -> 0 | Q11: =IF(A11="","",COUNTA(L11:O11)) -> 0 | R11: =IF(A11="","",P11+Q11) -> 0 | S11: =IF(A11="","",IF(R11=0,"",IF(R11>4,"❌ Over 4 events",IF(AND(R11=4,NOT(OR(AND(P11=3,Q11=1),AND(P11=1,Q11=3)))),"⚠ Must be 3+1 or 1+3","✓ OK"))))
A12: =IF(Roster!A11="","",Roster!A11) -> Sage Houdek | B12: =IF(Roster!B11="","",Roster!B11) -> 8 | C12: =IF(Roster!C11="","",Roster!C11) -> F | G12: X | I12: X | P12: =IF(A12="","",COUNTA(D12:K12)) -> 2 | Q12: =IF(A12="","",COUNTA(L12:O12)) -> 0 | R12: =IF(A12="","",P12+Q12) -> 2 | S12: =IF(A12="","",IF(R12=0,"",IF(R12>4,"❌ Over 4 events",IF(AND(R12=4,NOT(OR(AND(P12=3,Q12=1),AND(P12=1,Q12=3)))),"⚠ Must be 3+1 or 1+3","✓ OK")))) -> ✓ OK
A13: =IF(Roster!A12="","",Roster!A12) -> Ari Klapperich-Khuu | B13: =IF(Roster!B12="","",Roster!B12) -> 7 | C13: =IF(Roster!C12="","",Roster!C12) -> M | D13: X | E13: X | H13: B | K13: B | P13: =IF(A13="","",COUNTA(D13:K13)) -> 4 | Q13: =IF(A13="","",COUNTA(L13:O13)) -> 0 | R13: =IF(A13="","",P13+Q13) -> 4 | S13: =IF(A13="","",IF(R13=0,"",IF(R13>4,"❌ Over 4 events",IF(AND(R13=4,NOT(OR(AND(P13=3,Q13=1),AND(P13=1,Q13=3)))),"⚠ Must be 3+1 or 1+3","✓ OK")))) -> ⚠ Must be 3+1 or 1+3
A14: =IF(Roster!A13="","",Roster!A13) -> Marcus Kunc | B14: =IF(Roster!B13="","",Roster!B13) -> 6 | C14: =IF(Roster!C13="","",Roster!C13) -> M | P14: =IF(A14="","",COUNTA(D14:K14)) -> 0 | Q14: =IF(A14="","",COUNTA(L14:O14)) -> 0 | R14: =IF(A14="","",P14+Q14) -> 0 | S14: =IF(A14="","",IF(R14=0,"",IF(R14>4,"❌ Over 4 events",IF(AND(R14=4,NOT(OR(AND(P14=3,Q14=1),AND(P14=1,Q14=3)))),"⚠ Must be 3+1 or 1+3","✓ OK"))))
A15: =IF(Roster!A14="","",Roster!A14) -> Mattias Kunc | B15: =IF(Roster!B14="","",Roster!B14) -> 8 | C15: =IF(Roster!C14="","",Roster!C14) -> M | P15: =IF(A15="","",COUNTA(D15:K15)) -> 0 | Q15: =IF(A15="","",COUNTA(L15:O15)) -> 0 | R15: =IF(A15="","",P15+Q15) -> 0 | S15: =IF(A15="","",IF(R15=0,"",IF(R15>4,"❌ Over 4 events",IF(AND(R15=4,NOT(OR(AND(P15=3,Q15=1),AND(P15=1,Q15=3)))),"⚠ Must be 3+1 or 1+3","✓ OK"))))
A16: =IF(Roster!A15="","",Roster!A15) -> Gabriel Nowariak | B16: =IF(Roster!B15="","",Roster!B15) -> 6 | C16: =IF(Roster!C15="","",Roster!C15) -> M | F16: X | I16: X | M16: X | O16: X | P16: =IF(A16="","",COUNTA(D16:K16)) -> 2 | Q16: =IF(A16="","",COUNTA(L16:O16)) -> 2 | R16: =IF(A16="","",P16+Q16) -> 4 | S16: =IF(A16="","",IF(R16=0,"",IF(R16>4,"❌ Over 4 events",IF(AND(R16=4,NOT(OR(AND(P16=3,Q16=1),AND(P16=1,Q16=3)))),"⚠ Must be 3+1 or 1+3","✓ OK")))) -> ⚠ Must be 3+1 or 1+3
A17: =IF(Roster!A16="","",Roster!A16) -> Annika Peterson | B17: =IF(Roster!B16="","",Roster!B16) -> 7 | C17: =IF(Roster!C16="","",Roster!C16) -> F | E17: X | F17: X | H17: A | J17: X | K17: A | M17: X | P17: =IF(A17="","",COUNTA(D17:K17)) -> 5 | Q17: =IF(A17="","",COUNTA(L17:O17)) -> 1 | R17: =IF(A17="","",P17+Q17) -> 6 | S17: =IF(A17="","",IF(R17=0,"",IF(R17>4,"❌ Over 4 events",IF(AND(R17=4,NOT(OR(AND(P17=3,Q17=1),AND(P17=1,Q17=3)))),"⚠ Must be 3+1 or 1+3","✓ OK")))) -> ❌ Over 4 events
A18: =IF(Roster!A17="","",Roster!A17) -> Amelia Roddy | B18: =IF(Roster!B17="","",Roster!B17) -> 6 | C18: =IF(Roster!C17="","",Roster!C17) -> F | H18: C | P18: =IF(A18="","",COUNTA(D18:K18)) -> 1 | Q18: =IF(A18="","",COUNTA(L18:O18)) -> 0 | R18: =IF(A18="","",P18+Q18) -> 1 | S18: =IF(A18="","",IF(R18=0,"",IF(R18>4,"❌ Over 4 events",IF(AND(R18=4,NOT(OR(AND(P18=3,Q18=1),AND(P18=1,Q18=3)))),"⚠ Must be 3+1 or 1+3","✓ OK")))) -> ✓ OK
A19: =IF(Roster!A18="","",Roster!A18) -> Audrey Roffe | B19: =IF(Roster!B18="","",Roster!B18) -> 7 | C19: =IF(Roster!C18="","",Roster!C18) -> F | F19: X | M19: X | P19: =IF(A19="","",COUNTA(D19:K19)) -> 1 | Q19: =IF(A19="","",COUNTA(L19:O19)) -> 1 | R19: =IF(A19="","",P19+Q19) -> 2 | S19: =IF(A19="","",IF(R19=0,"",IF(R19>4,"❌ Over 4 events",IF(AND(R19=4,NOT(OR(AND(P19=3,Q19=1),AND(P19=1,Q19=3)))),"⚠ Must be 3+1 or 1+3","✓ OK")))) -> ✓ OK
A20: =IF(Roster!A19="","",Roster!A19) -> Louis Ryan | B20: =IF(Roster!B19="","",Roster!B19) -> 7 | C20: =IF(Roster!C19="","",Roster!C19) -> M | E20: X | J20: X | O20: X | P20: =IF(A20="","",COUNTA(D20:K20)) -> 2 | Q20: =IF(A20="","",COUNTA(L20:O20)) -> 1 | R20: =IF(A20="","",P20+Q20) -> 3 | S20: =IF(A20="","",IF(R20=0,"",IF(R20>4,"❌ Over 4 events",IF(AND(R20=4,NOT(OR(AND(P20=3,Q20=1),AND(P20=1,Q20=3)))),"⚠ Must be 3+1 or 1+3","✓ OK")))) -> ✓ OK
A21: =IF(Roster!A20="","",Roster!A20) -> Arya Sanaka | B21: =IF(Roster!B20="","",Roster!B20) -> 7 | C21: =IF(Roster!C20="","",Roster!C20) -> M | E21: X | I21: X | L21: X | M21: X | P21: =IF(A21="","",COUNTA(D21:K21)) -> 2 | Q21: =IF(A21="","",COUNTA(L21:O21)) -> 2 | R21: =IF(A21="","",P21+Q21) -> 4 | S21: =IF(A21="","",IF(R21=0,"",IF(R21>4,"❌ Over 4 events",IF(AND(R21=4,NOT(OR(AND(P21=3,Q21=1),AND(P21=1,Q21=3)))),"⚠ Must be 3+1 or 1+3","✓ OK")))) -> ⚠ Must be 3+1 or 1+3
A22: =IF(Roster!A21="","",Roster!A21) -> Ben Surla | B22: =IF(Roster!B21="","",Roster!B21) -> 7 | C22: =IF(Roster!C21="","",Roster!C21) -> M | E22: X | F22: X | J22: X | P22: =IF(A22="","",COUNTA(D22:K22)) -> 3 | Q22: =IF(A22="","",COUNTA(L22:O22)) -> 0 | R22: =IF(A22="","",P22+Q22) -> 3 | S22: =IF(A22="","",IF(R22=0,"",IF(R22>4,"❌ Over 4 events",IF(AND(R22=4,NOT(OR(AND(P22=3,Q22=1),AND(P22=1,Q22=3)))),"⚠ Must be 3+1 or 1+3","✓ OK")))) -> ✓ OK
A23: =IF(Roster!A22="","",Roster!A22) -> Jin Trenh | B23: =IF(Roster!B22="","",Roster!B22) -> 8 | C23: =IF(Roster!C22="","",Roster!C22) -> M | E23: X | H23: X | I23: X | P23: =IF(A23="","",COUNTA(D23:K23)) -> 3 | Q23: =IF(A23="","",COUNTA(L23:O23)) -> 0 | R23: =IF(A23="","",P23+Q23) -> 3 | S23: =IF(A23="","",IF(R23=0,"",IF(R23>4,"❌ Over 4 events",IF(AND(R23=4,NOT(OR(AND(P23=3,Q23=1),AND(P23=1,Q23=3)))),"⚠ Must be 3+1 or 1+3","✓ OK")))) -> ✓ OK
A24: =IF(Roster!A23="","",Roster!A23) -> Caleb Wilson | B24: =IF(Roster!B23="","",Roster!B23) -> 7 | C24: =IF(Roster!C23="","",Roster!C23) -> M | E24: X | I24: X | J24: X | O24: X | P24: =IF(A24="","",COUNTA(D24:K24)) -> 3 | Q24: =IF(A24="","",COUNTA(L24:O24)) -> 1 | R24: =IF(A24="","",P24+Q24) -> 4 | S24: =IF(A24="","",IF(R24=0,"",IF(R24>4,"❌ Over 4 events",IF(AND(R24=4,NOT(OR(AND(P24=3,Q24=1),AND(P24=1,Q24=3)))),"⚠ Must be 3+1 or 1+3","✓ OK")))) -> ✓ OK
A25: =IF(Roster!A24="","",Roster!A24) -> Isaac Wilson | B25: =IF(Roster!B24="","",Roster!B24) -> 7 | C25: =IF(Roster!C24="","",Roster!C24) -> M | H25: B | K25: B | P25: =IF(A25="","",COUNTA(D25:K25)) -> 2 | Q25: =IF(A25="","",COUNTA(L25:O25)) -> 0 | R25: =IF(A25="","",P25+Q25) -> 2 | S25: =IF(A25="","",IF(R25=0,"",IF(R25>4,"❌ Over 4 events",IF(AND(R25=4,NOT(OR(AND(P25=3,Q25=1),AND(P25=1,Q25=3)))),"⚠ Must be 3+1 or 1+3","✓ OK")))) -> ✓ OK
A26: Perrin Light-Haberstroh | B26: =IF(Roster!B25="","",Roster!B25) -> 7 | C26: =IF(Roster!C25="","",Roster!C25) -> M | E26: X | H26: C | I26: X | M26: X | P26: =IF(A26="","",COUNTA(D26:K26)) -> 3 | Q26: =IF(A26="","",COUNTA(L26:O26)) -> 1 | R26: =IF(A26="","",P26+Q26) -> 4 | S26: =IF(A26="","",IF(R26=0,"",IF(R26>4,"❌ Over 4 events",IF(AND(R26=4,NOT(OR(AND(P26=3,Q26=1),AND(P26=1,Q26=3)))),"⚠ Must be 3+1 or 1+3","✓ OK")))) -> ✓ OK
A27: Nathan Coblentz | B27: =IF(Roster!B26="","",Roster!B26) | C27: =IF(Roster!C26="","",Roster!C26) | E27: X | G27: X | I27: X | P27: =IF(A27="","",COUNTA(D27:K27)) -> 3 | Q27: =IF(A27="","",COUNTA(L27:O27)) -> 0 | R27: =IF(A27="","",P27+Q27) -> 3 | S27: =IF(A27="","",IF(R27=0,"",IF(R27>4,"❌ Over 4 events",IF(AND(R27=4,NOT(OR(AND(P27=3,Q27=1),AND(P27=1,Q27=3)))),"⚠ Must be 3+1 or 1+3","✓ OK")))) -> ✓ OK
A28: Alex Ebinger | B28: =IF(Roster!B27="","",Roster!B27) | C28: =IF(Roster!C27="","",Roster!C27) | E28: X | H28: C | I28: X | M28: X | P28: =IF(A28="","",COUNTA(D28:K28)) -> 3 | Q28: =IF(A28="","",COUNTA(L28:O28)) -> 1 | R28: =IF(A28="","",P28+Q28) -> 4 | S28: =IF(A28="","",IF(R28=0,"",IF(R28>4,"❌ Over 4 events",IF(AND(R28=4,NOT(OR(AND(P28=3,Q28=1),AND(P28=1,Q28=3)))),"⚠ Must be 3+1 or 1+3","✓ OK")))) -> ✓ OK
A29: Cooper Coblentz | B29: =IF(Roster!B28="","",Roster!B28) | C29: =IF(Roster!C28="","",Roster!C28) | E29: X | G29: X | O29: X | P29: =IF(A29="","",COUNTA(D29:K29)) -> 2 | Q29: =IF(A29="","",COUNTA(L29:O29)) -> 1 | R29: =IF(A29="","",P29+Q29) -> 3 | S29: =IF(A29="","",IF(R29=0,"",IF(R29>4,"❌ Over 4 events",IF(AND(R29=4,NOT(OR(AND(P29=3,Q29=1),AND(P29=1,Q29=3)))),"⚠ Must be 3+1 or 1+3","✓ OK")))) -> ✓ OK
A30: =IF(Roster!A29="","",Roster!A29) -> Cole Beaudry | B30: =IF(Roster!B29="","",Roster!B29) -> 7 | C30: =IF(Roster!C29="","",Roster!C29) -> M | D30: X | H30: B | J30: X | K30: B | P30: =IF(A30="","",COUNTA(D30:K30)) -> 4 | Q30: =IF(A30="","",COUNTA(L30:O30)) -> 0 | R30: =IF(A30="","",P30+Q30) -> 4 | S30: =IF(A30="","",IF(R30=0,"",IF(R30>4,"❌ Over 4 events",IF(AND(R30=4,NOT(OR(AND(P30=3,Q30=1),AND(P30=1,Q30=3)))),"⚠ Must be 3+1 or 1+3","✓ OK")))) -> ⚠ Must be 3+1 or 1+3
A31: Thea Bortel | B31: =IF(Roster!B30="","",Roster!B30) | C31: =IF(Roster!C30="","",Roster!C30) | H31: A | I31: X | K31: A | M31: X | P31: =IF(A31="","",COUNTA(D31:K31)) -> 3 | Q31: =IF(A31="","",COUNTA(L31:O31)) -> 1 | R31: =IF(A31="","",P31+Q31) -> 4 | S31: =IF(A31="","",IF(R31=0,"",IF(R31>4,"❌ Over 4 events",IF(AND(R31=4,NOT(OR(AND(P31=3,Q31=1),AND(P31=1,Q31=3)))),"⚠ Must be 3+1 or 1+3","✓ OK")))) -> ✓ OK
A32: Devin Linquist | B32: =IF(Roster!B31="","",Roster!B31) | C32: =IF(Roster!C31="","",Roster!C31) | E32: X | G32: X | I32: X | O32: X | P32: =IF(A32="","",COUNTA(D32:K32)) -> 3 | Q32: =IF(A32="","",COUNTA(L32:O32)) -> 1 | R32: =IF(A32="","",P32+Q32) -> 4 | S32: =IF(A32="","",IF(R32=0,"",IF(R32>4,"❌ Over 4 events",IF(AND(R32=4,NOT(OR(AND(P32=3,Q32=1),AND(P32=1,Q32=3)))),"⚠ Must be 3+1 or 1+3","✓ OK")))) -> ✓ OK
A33: Gabriel Nowariak | B33: =IF(Roster!B32="","",Roster!B32) | C33: =IF(Roster!C32="","",Roster!C32) | F33: X | I33: X | M33: X | O33: X | P33: =IF(A33="","",COUNTA(D33:K33)) -> 2 | Q33: =IF(A33="","",COUNTA(L33:O33)) -> 2 | R33: =IF(A33="","",P33+Q33) -> 4 | S33: =IF(A33="","",IF(R33=0,"",IF(R33>4,"❌ Over 4 events",IF(AND(R33=4,NOT(OR(AND(P33=3,Q33=1),AND(P33=1,Q33=3)))),"⚠ Must be 3+1 or 1+3","✓ OK")))) -> ⚠ Must be 3+1 or 1+3
A34: Addis demere | B34: =IF(Roster!B33="","",Roster!B33) | C34: =IF(Roster!C33="","",Roster!C33) | E34: X | H34: X | I34: X | K34: X | P34: =IF(A34="","",COUNTA(D34:K34)) -> 4 | Q34: =IF(A34="","",COUNTA(L34:O34)) -> 0 | R34: =IF(A34="","",P34+Q34) -> 4 | S34: =IF(A34="","",IF(R34=0,"",IF(R34>4,"❌ Over 4 events",IF(AND(R34=4,NOT(OR(AND(P34=3,Q34=1),AND(P34=1,Q34=3)))),"⚠ Must be 3+1 or 1+3","✓ OK")))) -> ⚠ Must be 3+1 or 1+3
A35: aedan herman | B35: =IF(Roster!B34="","",Roster!B34) | C35: =IF(Roster!C34="","",Roster!C34) | G35: X | H35: X | O35: X | P35: =IF(A35="","",COUNTA(D35:K35)) -> 2 | Q35: =IF(A35="","",COUNTA(L35:O35)) -> 1 | R35: =IF(A35="","",P35+Q35) -> 3 | S35: =IF(A35="","",IF(R35=0,"",IF(R35>4,"❌ Over 4 events",IF(AND(R35=4,NOT(OR(AND(P35=3,Q35=1),AND(P35=1,Q35=3)))),"⚠ Must be 3+1 or 1+3","✓ OK")))) -> ✓ OK
A36: Hudson Coblentz | B36: =IF(Roster!B35="","",Roster!B35) | C36: =IF(Roster!C35="","",Roster!C35) | E36: X | H36: X | I36: X | M36: X | P36: =IF(A36="","",COUNTA(D36:K36)) -> 3 | Q36: =IF(A36="","",COUNTA(L36:O36)) -> 1 | R36: =IF(A36="","",P36+Q36) -> 4 | S36: =IF(A36="","",IF(R36=0,"",IF(R36>4,"❌ Over 4 events",IF(AND(R36=4,NOT(OR(AND(P36=3,Q36=1),AND(P36=1,Q36=3)))),"⚠ Must be 3+1 or 1+3","✓ OK")))) -> ✓ OK
A37: =IF(Roster!A36="","",Roster!A36) | B37: =IF(Roster!B36="","",Roster!B36) | C37: =IF(Roster!C36="","",Roster!C36) | P37: =IF(A37="","",COUNTA(D37:K37)) | Q37: =IF(A37="","",COUNTA(L37:O37)) | R37: =IF(A37="","",P37+Q37) | S37: =IF(A37="","",IF(R37=0,"",IF(R37>4,"❌ Over 4 events",IF(AND(R37=4,NOT(OR(AND(P37=3,Q37=1),AND(P37=1,Q37=3)))),"⚠ Must be 3+1 or 1+3","✓ OK"))))
A38: =IF(Roster!A37="","",Roster!A37) | B38: =IF(Roster!B37="","",Roster!B37) | C38: =IF(Roster!C37="","",Roster!C37) | P38: =IF(A38="","",COUNTA(D38:K38)) | Q38: =IF(A38="","",COUNTA(L38:O38)) | R38: =IF(A38="","",P38+Q38) | S38: =IF(A38="","",IF(R38=0,"",IF(R38>4,"❌ Over 4 events",IF(AND(R38=4,NOT(OR(AND(P38=3,Q38=1),AND(P38=1,Q38=3)))),"⚠ Must be 3+1 or 1+3","✓ OK"))))
A39: =IF(Roster!A38="","",Roster!A38) | B39: =IF(Roster!B38="","",Roster!B38) | C39: =IF(Roster!C38="","",Roster!C38) | P39: =IF(A39="","",COUNTA(D39:K39)) | Q39: =IF(A39="","",COUNTA(L39:O39)) | R39: =IF(A39="","",P39+Q39) | S39: =IF(A39="","",IF(R39=0,"",IF(R39>4,"❌ Over 4 events",IF(AND(R39=4,NOT(OR(AND(P39=3,Q39=1),AND(P39=1,Q39=3)))),"⚠ Must be 3+1 or 1+3","✓ OK"))))

Sheet By Event
A1: By Event — Prior Lake Meet (auto-populated heat sheet)
A3: RUNNING EVENTS
A4: 100m Low Hurdles
A5: 6/7 Girls | B5: =IFERROR(__xludf.DUMMYFUNCTION("IFERROR(TEXTJOIN("", "",TRUE,FILTER(Signup!$A$4:$A$28,(Signup!$D$4:$D$28=""X"")*(((Signup!$B$4:$B$28=6)+(Signup!$B$4:$B$28=7))>0)*(Signup!$C$4:$C$28=""F""))),"""")"),"Keva Bowron, Vienna Haas") -> Keva Bowron, Vienna Haas
A6: 8 Girls | B6: =IFERROR(__xludf.DUMMYFUNCTION("IFERROR(TEXTJOIN("", "",TRUE,FILTER(Signup!$A$4:$A$28,(Signup!$D$4:$D$28=""X"")*(Signup!$B$4:$B$28=8)*(Signup!$C$4:$C$28=""F""))),"""")"),"")
A7: 6/7 Boys | B7: =IFERROR(__xludf.DUMMYFUNCTION("IFERROR(TEXTJOIN("", "",TRUE,FILTER(Signup!$A$4:$A$28,(Signup!$D$4:$D$28=""X"")*(((Signup!$B$4:$B$28=6)+(Signup!$B$4:$B$28=7))>0)*(Signup!$C$4:$C$28=""M""))),"""")"),"Ari Klapperich-Khuu") -> Ari Klapperich-Khuu
A8: 8 Boys | B8: =IFERROR(__xludf.DUMMYFUNCTION("IFERROR(TEXTJOIN("", "",TRUE,FILTER(Signup!$A$4:$A$28,(Signup!$D$4:$D$28=""X"")*(Signup!$B$4:$B$28=8)*(Signup!$C$4:$C$28=""M""))),"""")"),"")
A9: 5th Grade Girls | B9: =IFERROR(__xludf.DUMMYFUNCTION("IFERROR(TEXTJOIN("", "",TRUE,FILTER(Signup!$A$4:$A$28,(Signup!$D$4:$D$28=""X"")*(Signup!$B$4:$B$28=5)*(Signup!$C$4:$C$28=""F""))),"""")"),"")
A10: 5th Grade Boys | B10: =IFERROR(__xludf.DUMMYFUNCTION("IFERROR(TEXTJOIN("", "",TRUE,FILTER(Signup!$A$4:$A$28,(Signup!$D$4:$D$28=""X"")*(Signup!$B$4:$B$28=5)*(Signup!$C$4:$C$28=""M""))),"""")"),"")
A12: 100m Dash
A13: 6/7 Girls | B13: =IFERROR(__xludf.DUMMYFUNCTION("IFERROR(TEXTJOIN("", "",TRUE,FILTER(Signup!$A$4:$A$28,(Signup!$E$4:$E$28=""X"")*(((Signup!$B$4:$B$28=6)+(Signup!$B$4:$B$28=7))>0)*(Signup!$C$4:$C$28=""F""))),"""")"),"Annika Peterson") -> Annika Peterson
A14: 8 Girls | B14: =IFERROR(__xludf.DUMMYFUNCTION("IFERROR(TEXTJOIN("", "",TRUE,FILTER(Signup!$A$4:$A$28,(Signup!$E$4:$E$28=""X"")*(Signup!$B$4:$B$28=8)*(Signup!$C$4:$C$28=""F""))),"""")"),"")
A15: 6/7 Boys | B15: =IFERROR(__xludf.DUMMYFUNCTION("IFERROR(TEXTJOIN("", "",TRUE,FILTER(Signup!$A$4:$A$28,(Signup!$E$4:$E$28=""X"")*(((Signup!$B$4:$B$28=6)+(Signup!$B$4:$B$28=7))>0)*(Signup!$C$4:$C$28=""M""))),"""")"),"Reuben Addington, Kai Dinger, Remy Fortin, Ari Klapperich-Khuu, Louis Ryan, Arya Sanaka, Ben Surla, Caleb Wilson, Perrin Light-Haberstroh") -> Reuben Addington, Kai Dinger, Remy Fortin, Ari Klapperich-Khuu, Louis Ryan, Arya Sanaka, Ben Surla, Caleb Wilson, Perrin Light-Haberstroh
A16: 8 Boys | B16: =IFERROR(__xludf.DUMMYFUNCTION("IFERROR(TEXTJOIN("", "",TRUE,FILTER(Signup!$A$4:$A$28,(Signup!$E$4:$E$28=""X"")*(Signup!$B$4:$B$28=8)*(Signup!$C$4:$C$28=""M""))),"""")"),"Jin Trenh") -> Jin Trenh
A17: 5th Grade Girls | B17: =IFERROR(__xludf.DUMMYFUNCTION("IFERROR(TEXTJOIN("", "",TRUE,FILTER(Signup!$A$4:$A$28,(Signup!$E$4:$E$28=""X"")*(Signup!$B$4:$B$28=5)*(Signup!$C$4:$C$28=""F""))),"""")"),"")
A18: 5th Grade Boys | B18: =IFERROR(__xludf.DUMMYFUNCTION("IFERROR(TEXTJOIN("", "",TRUE,FILTER(Signup!$A$4:$A$28,(Signup!$E$4:$E$28=""X"")*(Signup!$B$4:$B$28=5)*(Signup!$C$4:$C$28=""M""))),"""")"),"")
A20: 1600m Run
A21: 6/7 Girls | B21: =IFERROR(__xludf.DUMMYFUNCTION("IFERROR(TEXTJOIN("", "",TRUE,FILTER(Signup!$A$4:$A$28,(Signup!$F$4:$F$28=""X"")*(((Signup!$B$4:$B$28=6)+(Signup!$B$4:$B$28=7))>0)*(Signup!$C$4:$C$28=""F""))),"""")"),"Annika Peterson, Audrey Roffe") -> Annika Peterson, Audrey Roffe
A22: 8 Girls | B22: =IFERROR(__xludf.DUMMYFUNCTION("IFERROR(TEXTJOIN("", "",TRUE,FILTER(Signup!$A$4:$A$28,(Signup!$F$4:$F$28=""X"")*(Signup!$B$4:$B$28=8)*(Signup!$C$4:$C$28=""F""))),"""")"),"")
A23: 6/7 Boys | B23: =IFERROR(__xludf.DUMMYFUNCTION("IFERROR(TEXTJOIN("", "",TRUE,FILTER(Signup!$A$4:$A$28,(Signup!$F$4:$F$28=""X"")*(((Signup!$B$4:$B$28=6)+(Signup!$B$4:$B$28=7))>0)*(Signup!$C$4:$C$28=""M""))),"""")"),"Gabriel Nowariak, Ben Surla") -> Gabriel Nowariak, Ben Surla
A24: 8 Boys | B24: =IFERROR(__xludf.DUMMYFUNCTION("IFERROR(TEXTJOIN("", "",TRUE,FILTER(Signup!$A$4:$A$28,(Signup!$F$4:$F$28=""X"")*(Signup!$B$4:$B$28=8)*(Signup!$C$4:$C$28=""M""))),"""")"),"")
A25: 5th Grade Girls | B25: =IFERROR(__xludf.DUMMYFUNCTION("IFERROR(TEXTJOIN("", "",TRUE,FILTER(Signup!$A$4:$A$28,(Signup!$F$4:$F$28=""X"")*(Signup!$B$4:$B$28=5)*(Signup!$C$4:$C$28=""F""))),"""")"),"")
A26: 5th Grade Boys | B26: =IFERROR(__xludf.DUMMYFUNCTION("IFERROR(TEXTJOIN("", "",TRUE,FILTER(Signup!$A$4:$A$28,(Signup!$F$4:$F$28=""X"")*(Signup!$B$4:$B$28=5)*(Signup!$C$4:$C$28=""M""))),"""")"),"")
A28: 400m Dash
A29: 6/7 Girls | B29: =IFERROR(__xludf.DUMMYFUNCTION("IFERROR(TEXTJOIN("", "",TRUE,FILTER(Signup!$A$4:$A$28,(Signup!$G$4:$G$28=""X"")*(((Signup!$B$4:$B$28=6)+(Signup!$B$4:$B$28=7))>0)*(Signup!$C$4:$C$28=""F""))),"""")"),"")
A30: 8 Girls | B30: =IFERROR(__xludf.DUMMYFUNCTION("IFERROR(TEXTJOIN("", "",TRUE,FILTER(Signup!$A$4:$A$28,(Signup!$G$4:$G$28=""X"")*(Signup!$B$4:$B$28=8)*(Signup!$C$4:$C$28=""F""))),"""")"),"Sage Houdek") -> Sage Houdek
A31: 6/7 Boys | B31: =IFERROR(__xludf.DUMMYFUNCTION("IFERROR(TEXTJOIN("", "",TRUE,FILTER(Signup!$A$4:$A$28,(Signup!$G$4:$G$28=""X"")*(((Signup!$B$4:$B$28=6)+(Signup!$B$4:$B$28=7))>0)*(Signup!$C$4:$C$28=""M""))),"""")"),"")
A32: 8 Boys | B32: =IFERROR(__xludf.DUMMYFUNCTION("IFERROR(TEXTJOIN("", "",TRUE,FILTER(Signup!$A$4:$A$28,(Signup!$G$4:$G$28=""X"")*(Signup!$B$4:$B$28=8)*(Signup!$C$4:$C$28=""M""))),"""")"),"")
A33: 5th Grade Girls | B33: =IFERROR(__xludf.DUMMYFUNCTION("IFERROR(TEXTJOIN("", "",TRUE,FILTER(Signup!$A$4:$A$28,(Signup!$G$4:$G$28=""X"")*(Signup!$B$4:$B$28=5)*(Signup!$C$4:$C$28=""F""))),"""")"),"")
A34: 5th Grade Boys | B34: =IFERROR(__xludf.DUMMYFUNCTION("IFERROR(TEXTJOIN("", "",TRUE,FILTER(Signup!$A$4:$A$28,(Signup!$G$4:$G$28=""X"")*(Signup!$B$4:$B$28=5)*(Signup!$C$4:$C$28=""M""))),"""")"),"")
A36: 4x100m Relay
A37: Team A | B37: =IFERROR(__xludf.DUMMYFUNCTION("IFERROR(TEXTJOIN("", "",TRUE,FILTER(Signup!$A$4:$A$28,Signup!$H$4:$H$28=""A"")),"""")"),"Keva Bowron, Vienna Haas, Annika Peterson") -> Keva Bowron, Vienna Haas, Annika Peterson
A38: Team B | B38: =IFERROR(__xludf.DUMMYFUNCTION("IFERROR(TEXTJOIN("", "",TRUE,FILTER(Signup!$A$4:$A$28,Signup!$H$4:$H$28=""B"")),"""")"),"Kai Dinger, Ari Klapperich-Khuu, Isaac Wilson") -> Kai Dinger, Ari Klapperich-Khuu, Isaac Wilson
A39: Team C | B39: =IFERROR(__xludf.DUMMYFUNCTION("IFERROR(TEXTJOIN("", "",TRUE,FILTER(Signup!$A$4:$A$28,Signup!$H$4:$H$28=""C"")),"""")"),"Elyse Folbrecht, Amelia Roddy, Perrin Light-Haberstroh, Alex Ebinger") -> Elyse Folbrecht, Amelia Roddy, Perrin Light-Haberstroh, Alex Ebinger
A40: Team D | B40: =IFERROR(__xludf.DUMMYFUNCTION("IFERROR(TEXTJOIN("", "",TRUE,FILTER(Signup!$A$4:$A$28,Signup!$H$4:$H$28=""D"")),"""")"),"")
A42: 200m Dash
A43: 6/7 Girls | B43: =IFERROR(__xludf.DUMMYFUNCTION("IFERROR(TEXTJOIN("", "",TRUE,FILTER(Signup!$A$4:$A$28,(Signup!$I$4:$I$28=""X"")*(((Signup!$B$4:$B$28=6)+(Signup!$B$4:$B$28=7))>0)*(Signup!$C$4:$C$28=""F""))),"""")"),"Keva Bowron") -> Keva Bowron
A44: 8 Girls | B44: =IFERROR(__xludf.DUMMYFUNCTION("IFERROR(TEXTJOIN("", "",TRUE,FILTER(Signup!$A$4:$A$28,(Signup!$I$4:$I$28=""X"")*(Signup!$B$4:$B$28=8)*(Signup!$C$4:$C$28=""F""))),"""")"),"Sage Houdek") -> Sage Houdek
A45: 6/7 Boys | B45: =IFERROR(__xludf.DUMMYFUNCTION("IFERROR(TEXTJOIN("", "",TRUE,FILTER(Signup!$A$4:$A$28,(Signup!$I$4:$I$28=""X"")*(((Signup!$B$4:$B$28=6)+(Signup!$B$4:$B$28=7))>0)*(Signup!$C$4:$C$28=""M""))),"""")"),"Kai Dinger, Remy Fortin, Gabriel Nowariak, Arya Sanaka, Caleb Wilson, Perrin Light-Haberstroh") -> Kai Dinger, Remy Fortin, Gabriel Nowariak, Arya Sanaka, Caleb Wilson, Perrin Light-Haberstroh
A46: 8 Boys | B46: =IFERROR(__xludf.DUMMYFUNCTION("IFERROR(TEXTJOIN("", "",TRUE,FILTER(Signup!$A$4:$A$28,(Signup!$I$4:$I$28=""X"")*(Signup!$B$4:$B$28=8)*(Signup!$C$4:$C$28=""M""))),"""")"),"Jin Trenh") -> Jin Trenh
...
