Workbook

Sheet Instructions
A1: Yinghua Track — 2026 Event Signup
A3: How to use this workbook
A5: 1) ROSTER tab — add/remove athletes here. Name, Grade, Gender (M or F).
A6: Grade and Gender are required — they control which heat each athlete runs in on the By Event tab.
A8: 2) SIGNUP tab — one row per athlete. Type into the event columns:
A9: • X = athlete is in this event (individual)
A10: • A or B or C or D = relay team letter (4x100 / 4x200 / 4x400)
A11: Leave cells blank if the athlete isn't in that event.
A13: 3) The right-side summary columns auto-count for you:
A14: • Run # — number of running events (relay counts as 1)
A15: • Field # — number of field events
A16: • Total — all events. Max allowed = 4. Turns RED when over.
... A32: then share the doc. All formulas, dropdowns, and conditional formatting carry over.

Sheet Roster
A1: Roster — edit here to add/remove athletes
A2: Name | B2: Grade | C2: Gender (M/F)
A3: Reuben Addington | B3: 6 | C3: M
A4: Cole Beaudry | B4: 7 | C4: M
A5: Althea Bortel Fielder | B5: 7 | C5: F
A6: Keva Bowron | B6: 7 | C6: F
A7: Liam Bursell | B7: 7 | C7: M
A8: Mila Bursell | B8: 7 | C8: F
A9: Grayson Chon | B9: 7 | C9: M
A10: Cooper Coblentz | B10: 8 | C10: M
A11: Hudson Coblentz | B11: 8 | C11: M
A12: Nathan Coblentz | B12: 8 | C12: M
A13: Addis Demere | B13: 8 | C13: M
A14: Kai Dinger | B14: 7 | C14: M
... A41: Isaac Wilson | B41: 7 | C41: M

Sheet Signup
A1: Athlete Event Signup
D2: RUNNING EVENTS (type X, or A/B/C/D for relays) | M2: FIELD EVENTS (type X) | R2: SUMMARY
A3: Name | B3: Grade | C3: Gender | D3: 75mH | E3: 100m | F3: 4x200 | G3: 1600m | H3: 4x100 | I3: 400m | J3: 800m | K3: 200m | L3: 4x400 | M3: SP | N3: DISC | O3: LJ | P3: TJ | Q3: HJ | R3: Run # | S3: Field # | T3: Total | U3: Valid?
A4: =IF(Roster!A3="","",Roster!A3) | B4: =IF(Roster!B3="","",Roster!B3) | C4: =IF(Roster!C3="","",Roster!C3) | R4: =IF(A4="","",COUNTA(D4:L4)) | S4: =IF(A4="","",COUNTA(M4:Q4)) | T4: =IF(A4="","",R4+S4) | U4: =IF(A4="","",IF(T4=0,"",IF(T4>4,"❌ Over 4 events",IF(AND(T4=4,NOT(OR(AND(R4=3,S4=1),AND(R4=1,S4=3)))),"⚠ Must be 3+1 or 1+3","✓ OK"))))
A5: =IF(Roster!A4="","",Roster!A4) | B5: =IF(Roster!B4="","",Roster!B4) | C5: =IF(Roster!C4="","",Roster!C4) | R5: =IF(A5="","",COUNTA(D5:L5)) | S5: =IF(A5="","",COUNTA(M5:Q5)) | T5: =IF(A5="","",R5+S5) | U5: =IF(A5="","",IF(T5=0,"",IF(T5>4,"❌ Over 4 events",IF(AND(T5=4,NOT(OR(AND(R5=3,S5=1),AND(R5=1,S5=3)))),"⚠ Must be 3+1 or 1+3","✓ OK"))))
A6: =IF(Roster!A5="","",Roster!A5) | B6: =IF(Roster!B5="","",Roster!B5) | C6: =IF(Roster!C5="","",Roster!C5) | R6: =IF(A6="","",COUNTA(D6:L6)) | S6: =IF(A6="","",COUNTA(M6:Q6)) | T6: =IF(A6="","",R6+S6) | U6: =IF(A6="","",IF(T6=0,"",IF(T6>4,"❌ Over 4 events",IF(AND(T6=4,NOT(OR(AND(R6=3,S6=1),AND(R6=1,S6=3)))),"⚠ Must be 3+1 or 1+3","✓ OK"))))
A7: =IF(Roster!A6="","",Roster!A6) | B7: =IF(Roster!B6="","",Roster!B6) | C7: =IF(Roster!C6="","",Roster!C6) | R7: =IF(A7="","",COUNTA(D7:L7)) | S7: =IF(A7="","",COUNTA(M7:Q7)) | T7: =IF(A7="","",R7+S7) | U7: =IF(A7="","",IF(T7=0,"",IF(T7>4,"❌ Over 4 events",IF(AND(T7=4,NOT(OR(AND(R7=3,S7=1),AND(R7=1,S7=3)))),"⚠ Must be 3+1 or 1+3","✓ OK"))))
A8: =IF(Roster!A7="","",Roster!A7) | B8: =IF(Roster!B7="","",Roster!B7) | C8: =IF(Roster!C7="","",Roster!C7) | R8: =IF(A8="","",COUNTA(D8:L8)) | S8: =IF(A8="","",COUNTA(M8:Q8)) | T8: =IF(A8="","",R8+S8) | U8: =IF(A8="","",IF(T8=0,"",IF(T8>4,"❌ Over 4 events",IF(AND(T8=4,NOT(OR(AND(R8=3,S8=1),AND(R8=1,S8=3)))),"⚠ Must be 3+1 or 1+3","✓ OK"))))
A9: =IF(Roster!A8="","",Roster!A8) | B9: =IF(Roster!B8="","",Roster!B8) | C9: =IF(Roster!C8="","",Roster!C8) | R9: =IF(A9="","",COUNTA(D9:L9)) | S9: =IF(A9="","",COUNTA(M9:Q9)) | T9: =IF(A9="","",R9+S9) | U9: =IF(A9="","",IF(T9=0,"",IF(T9>4,"❌ Over 4 events",IF(AND(T9=4,NOT(OR(AND(R9=3,S9=1),AND(R9=1,S9=3)))),"⚠ Must be 3+1 or 1+3","✓ OK"))))
A10: =IF(Roster!A9="","",Roster!A9) | B10: =IF(Roster!B9="","",Roster!B9) | C10: =IF(Roster!C9="","",Roster!C9) | R10: =IF(A10="","",COUNTA(D10:L10)) | S10: =IF(A10="","",COUNTA(M10:Q10)) | T10: =IF(A10="","",R10+S10) | U10: =IF(A10="","",IF(T10=0,"",IF(T10>4,"❌ Over 4 events",IF(AND(T10=4,NOT(OR(AND(R10=3,S10=1),AND(R10=1,S10=3)))),"⚠ Must be 3+1 or 1+3","✓ OK"))))
A11: =IF(Roster!A10="","",Roster!A10) | B11: =IF(Roster!B10="","",Roster!B10) | C11: =IF(Roster!C10="","",Roster!C10) | R11: =IF(A11="","",COUNTA(D11:L11)) | S11: =IF(A11="","",COUNTA(M11:Q11)) | T11: =IF(A11="","",R11+S11) | U11: =IF(A11="","",IF(T11=0,"",IF(T11>4,"❌ Over 4 events",IF(AND(T11=4,NOT(OR(AND(R11=3,S11=1),AND(R11=1,S11=3)))),"⚠ Must be 3+1 or 1+3","✓ OK"))))
A12: =IF(Roster!A11="","",Roster!A11) | B12: =IF(Roster!B11="","",Roster!B11) | C12: =IF(Roster!C11="","",Roster!C11) | R12: =IF(A12="","",COUNTA(D12:L12)) | S12: =IF(A12="","",COUNTA(M12:Q12)) | T12: =IF(A12="","",R12+S12) | U12: =IF(A12="","",IF(T12=0,"",IF(T12>4,"❌ Over 4 events",IF(AND(T12=4,NOT(OR(AND(R12=3,S12=1),AND(R12=1,S12=3)))),"⚠ Must be 3+1 or 1+3","✓ OK"))))
A13: =IF(Roster!A12="","",Roster!A12) | B13: =IF(Roster!B12="","",Roster!B12) | C13: =IF(Roster!C12="","",Roster!C12) | R13: =IF(A13="","",COUNTA(D13:L13)) | S13: =IF(A13="","",COUNTA(M13:Q13)) | T13: =IF(A13="","",R13+S13) | U13: =IF(A13="","",IF(T13=0,"",IF(T13>4,"❌ Over 4 events",IF(AND(T13=4,NOT(OR(AND(R13=3,S13=1),AND(R13=1,S13=3)))),"⚠ Must be 3+1 or 1+3","✓ OK"))))
A14: =IF(Roster!A13="","",Roster!A13) | B14: =IF(Roster!B13="","",Roster!B13) | C14: =IF(Roster!C13="","",Roster!C13) | R14: =IF(A14="","",COUNTA(D14:L14)) | S14: =IF(A14="","",COUNTA(M14:Q14)) | T14: =IF(A14="","",R14+S14) | U14: =IF(A14="","",IF(T14=0,"",IF(T14>4,"❌ Over 4 events",IF(AND(T14=4,NOT(OR(AND(R14=3,S14=1),AND(R14=1,S14=3)))),"⚠ Must be 3+1 or 1+3","✓ OK"))))
A15: =IF(Roster!A14="","",Roster!A14) | B15: =IF(Roster!B14="","",Roster!B14) | C15: =IF(Roster!C14="","",Roster!C14) | R15: =IF(A15="","",COUNTA(D15:L15)) | S15: =IF(A15="","",COUNTA(M15:Q15)) | T15: =IF(A15="","",R15+S15) | U15: =IF(A15="","",IF(T15=0,"",IF(T15>4,"❌ Over 4 events",IF(AND(T15=4,NOT(OR(AND(R15=3,S15=1),AND(R15=1,S15=3)))),"⚠ Must be 3+1 or 1+3","✓ OK"))))
... A52: =IF(Roster!A51="","",Roster!A51) | B52: =IF(Roster!B51="","",Roster!B51) | C52: =IF(Roster!C51="","",Roster!C51) | R52: =IF(A52="","",COUNTA(D52:L52)) | S52: =IF(A52="","",COUNTA(M52:Q52)) | T52: =IF(A52="","",R52+S52) | U52: =IF(A52="","",IF(T52=0,"",IF(T52>4,"❌ Over 4 events",IF(AND(T52=4,NOT(OR(AND(R52=3,S52=1),AND(R52=1,S52=3)))),"⚠ Must be 3+1 or 1+3","✓ OK"))))

Sheet By Event
A1: By Event — auto-populated heat sheet
A2: Running events run in order below. Heats within each event: 6/7G → 8G → 6/7B → 8B.
A4: RUNNING EVENTS (in conference order)
A5: 75m Hurdles
A6: 6/7 Girls | B6: =IFERROR(TEXTJOIN(", ",TRUE,FILTER(Signup!$A$4:$A$52,(Signup!$D$4:$D$52="X")*(((Signup!$B$4:$B$52=6)+(Signup!$B$4:$B$52=7))>0)*(Signup!$C$4:$C$52="F"))),"")
A7: 8 Girls | B7: =IFERROR(TEXTJOIN(", ",TRUE,FILTER(Signup!$A$4:$A$52,(Signup!$D$4:$D$52="X")*(Signup!$B$4:$B$52=8)*(Signup!$C$4:$C$52="F"))),"")
A8: 6/7 Boys | B8: =IFERROR(TEXTJOIN(", ",TRUE,FILTER(Signup!$A$4:$A$52,(Signup!$D$4:$D$52="X")*(((Signup!$B$4:$B$52=6)+(Signup!$B$4:$B$52=7))>0)*(Signup!$C$4:$C$52="M"))),"")
A9: 8 Boys | B9: =IFERROR(TEXTJOIN(", ",TRUE,FILTER(Signup!$A$4:$A$52,(Signup!$D$4:$D$52="X")*(Signup!$B$4:$B$52=8)*(Signup!$C$4:$C$52="M"))),"")
A11: 100m Dash
A12: 6/7 Girls | B12: =IFERROR(TEXTJOIN(", ",TRUE,FILTER(Signup!$A$4:$A$52,(Signup!$E$4:$E$52="X")*(((Signup!$B$4:$B$52=6)+(Signup!$B$4:$B$52=7))>0)*(Signup!$C$4:$C$52="F"))),"")
A13: 8 Girls | B13: =IFERROR(TEXTJOIN(", ",TRUE,FILTER(Signup!$A$4:$A$52,(Signup!$E$4:$E$52="X")*(Signup!$B$4:$B$52=8)*(Signup!$C$4:$C$52="F"))),"")
A14: 6/7 Boys | B14: =IFERROR(TEXTJOIN(", ",TRUE,FILTER(Signup!$A$4:$A$52,(Signup!$E$4:$E$52="X")*(((Signup!$B$4:$B$52=6)+(Signup!$B$4:$B$52=7))>0)*(Signup!$C$4:$C$52="M"))),"")
A15: 8 Boys | B15: =IFERROR(TEXTJOIN(", ",TRUE,FILTER(Signup!$A$4:$A$52,(Signup!$E$4:$E$52="X")*(Signup!$B$4:$B$52=8)*(Signup!$C$4:$C$52="M"))),"")
A17: 4x200m Relay
A18: Team A | B18: =IFERROR(TEXTJOIN(", ",TRUE,FILTER(Signup!$A$4:$A$52,Signup!$F$4:$F$52="A")),"")
A19: Team B | B19: =IFERROR(TEXTJOIN(", ",TRUE,FILTER(Signup!$A$4:$A$52,Signup!$F$4:$F$52="B")),"")
A20: Team C | B20: =IFERROR(TEXTJOIN(", ",TRUE,FILTER(Signup!$A$4:$A$52,Signup!$F$4:$F$52="C")),"")
A21: Team D | B21: =IFERROR(TEXTJOIN(", ",TRUE,FILTER(Signup!$A$4:$A$52,Signup!$F$4:$F$52="D")),"")
A23: 1600m Run
A24: 6/7 Girls | B24: =IFERROR(TEXTJOIN(", ",TRUE,FILTER(Signup!$A$4:$A$52,(Signup!$G$4:$G$52="X")*(((Signup!$B$4:$B$52=6)+(Signup!$B$4:$B$52=7))>0)*(Signup!$C$4:$C$52="F"))),"")
A25: 8 Girls | B25: =IFERROR(TEXTJOIN(", ",TRUE,FILTER(Signup!$A$4:$A$52,(Signup!$G$4:$G$52="X")*(Signup!$B$4:$B$52=8)*(Signup!$C$4:$C$52="F"))),"")
A26: 6/7 Boys | B26: =IFERROR(TEXTJOIN(", ",TRUE,FILTER(Signup!$A$4:$A$52,(Signup!$G$4:$G$52="X")*(((Signup!$B$4:$B$52=6)+(Signup!$B$4:$B$52=7))>0)*(Signup!$C$4:$C$52="M"))),"")
A27: 8 Boys | B27: =IFERROR(TEXTJOIN(", ",TRUE,FILTER(Signup!$A$4:$A$52,(Signup!$G$4:$G$52="X")*(Signup!$B$4:$B$52=8)*(Signup!$C$4:$C$52="M"))),"")
A29: 4x100m Relay
A30: Team A | B30: =IFERROR(TEXTJOIN(", ",TRUE,FILTER(Signup!$A$4:$A$52,Signup!$H$4:$H$52="A")),"")
A31: Team B | B31: =IFERROR(TEXTJOIN(", ",TRUE,FILTER(Signup!$A$4:$A$52,Signup!$H$4:$H$52="B")),"")
A32: Team C | B32: =IFERROR(TEXTJOIN(", ",TRUE,FILTER(Signup!$A$4:$A$52,Signup!$H$4:$H$52="C")),"")
A33: Team D | B33: =IFERROR(TEXTJOIN(", ",TRUE,FILTER(Signup!$A$4:$A$52,Signup!$H$4:$H$52="D")),"")
A35: 400m Dash
A36: 6/7 Girls | B36: =IFERROR(TEXTJOIN(", ",TRUE,FILTER(Signup!$A$4:$A$52,(Signup!$I$4:$I$52="X")*(((Signup!$B$4:$B$52=6)+(Signup!$B$4:$B$52=7))>0)*(Signup!$C$4:$C$52="F"))),"")
A37: 8 Girls | B37: =IFERROR(TEXTJOIN(", ",TRUE,FILTER(Signup!$A$4:$A$52,(Signup!$I$4:$I$52="X")*(Signup!$B$4:$B$52=8)*(Signup!$C$4:$C$52="F"))),"")
A38: 6/7 Boys | B38: =IFERROR(TEXTJOIN(", ",TRUE,FILTER(Signup!$A$4:$A$52,(Signup!$I$4:$I$52="X")*(((Signup!$B$4:$B$52=6)+(Signup!$B$4:$B$52=7))>0)*(Signup!$C$4:$C$52="M"))),"")
A39: 8 Boys | B39: =IFERROR(TEXTJOIN(", ",TRUE,FILTER(Signup!$A$4:$A$52,(Signup!$I$4:$I$52="X")*(Signup!$B$4:$B$52=8)*(Signup!$C$4:$C$52="M"))),"")
A41: 800m Run
A42: 6/7 Girls | B42: =IFERROR(TEXTJOIN(", ",TRUE,FILTER(Signup!$A$4:$A$52,(Signup!$J$4:$J$52="X")*(((Signup!$B$4:$B$52=6)+(Signup!$B$4:$B$52=7))>0)*(Signup!$C$4:$C$52="F"))),"")
A43: 8 Girls | B43: =IFERROR(TEXTJOIN(", ",TRUE,FILTER(Signup!$A$4:$A$52,(Signup!$J$4:$J$52="X")*(Signup!$B$4:$B$52=8)*(Signup!$C$4:$C$52="F"))),"")
A44: 6/7 Boys | B44: =IFERROR(TEXTJOIN(", ",TRUE,FILTER(Signup!$A$4:$A$52,(Signup!$J$4:$J$52="X")*(((Signup!$B$4:$B$52=6)+(Signup!$B$4:$B$52=7))>0)*(Signup!$C$4:$C$52="M"))),"")
A45: 8 Boys | B45: =IFERROR(TEXTJOIN(", ",TRUE,FILTER(Signup!$A$4:$A$52,(Signup!$J$4:$J$52="X")*(Signup!$B$4:$B$52=8)*(Signup!$C$4:$C$52="M"))),"")
A47: 200m Dash
A48: 6/7 Girls | B48: =IFERROR(TEXTJOIN(", ",TRUE,FILTER(Signup!$A$4:$A$52,(Signup!$K$4:$K$52="X")*(((Signup!$B$4:$B$52=6)+(Signup!$B$4:$B$52=7))>0)*(Signup!$C$4:$C$52="F"))),"")
...
